<?xml version="1.0"?>
<robot xmlns:xacro="http://www.ros.org/wiki/xacro">

  <!-- Định nghĩa macro cho một chân -->
  <xacro:macro name="leg" params="prefix pos side x y">
    <!-- bắt đầu phần háng -->
    <!-- Hip Link -->


    <link name="${prefix}_hip_link">
      <visual name="${prefix}_hip_visual">
        <xacro:if value="${(side == 'left')}">
          <origin xyz="0 0.055 0" rpy="0 0 0"/>
          <!-- vị trí đặt link - khớp háng so với body -->
        </xacro:if>
        <xacro:if value="${(side == 'right')}">
          <origin xyz="0 -0.055 0" rpy="0 0 0"/>
          <!-- vị trí đặt link - khớp háng so với body -->
        </xacro:if>
        <geometry>
          <box size="0.03 0.03 0.02"/>
          <!-- dài 2cm, cố định thân trên và các chân -->
        </geometry>
        <material name="blue"/>
      </visual>
      <collision name="${prefix}_hip_collision">
        <geometry>
          <box size="0.03 0.03 0.02"/>
          <!-- dài 2cm, cố định thân trên và các chân -->
        </geometry>
      </collision>
      <inertial>
        <mass value="0.2"/>
        <inertia ixx="0.000833" ixy="0.0" ixz="0.0" iyy="0.000833" iyz="0.0" izz="0.001666"/>
      </inertial>
    </link>

    <joint name="${prefix}_hip_joint" type="fixed">
      <parent link="${pos}_body"/>
      <child link="${prefix}_hip_link"/>
      <origin xyz="0 0 0.0" rpy="0 0 0"/>
      <!-- Vị trí gắn khớp háng vào body-->
    </joint>

    <!-- x1.1 Motor link vỏ motor mô phỏng, không quay -->
    <link name="${prefix}_hip_motor_link">
      <visual name="${prefix}_hip_motor_visual">
        <geometry>
          <cylinder radius="0.015" length="0.02"/>
        </geometry>
        <origin xyz="0.005 0 0" rpy="1.0 0 0"/>
        <xacro:if value="${(side == 'left')}">
          <origin xyz="0.005 0.055 0" rpy="1.5708 0 0"/>
          <!-- vị trí đặt link mô phỏng motor khớp háng- trái -->
        </xacro:if>
        <xacro:if value="${(side == 'right')}">
          <origin xyz="0.005 -0.055 0" rpy="1.5708 0 0"/>
          <!-- vị trí đặt link mô phỏng motor khớp háng- phải -->
        </xacro:if>
        <material name="yellow"/>
      </visual>
     <inertial>
        <mass value="0.5"/>
        <inertia ixx="0.000417" ixy="0.0" ixz="0.0" iyy="0.000417" iyz="0.0" izz="0.000833"/>
      </inertial>
    </link>

    <!-- x1.2 Gắn motor link mô phỏng vào body bằng joint cố định -->
    <joint name="${prefix}_hip_motor_fixed" type="fixed">
      <parent link="${prefix}_hip_link"/>
      <child link="${prefix}_hip_motor_link"/>
      <origin xyz="0 0 0.0" rpy="0 0 0"/>
      <!-- Vị trí gắn motor -->
    </joint>

    <!-- Kết thúc phần háng -->

    <!-- *** Bắt đầu phần đùi chân *** -->

    <!-- knee Link -->
    <link name="${prefix}_knee_link">
      <visual name="${prefix}_knee_visual">
        <xacro:if value="${(side == 'left')}">
          <origin xyz="0.005 0.055 -0.05" rpy="0 0 0"/>
          <!-- Vị trí đặt link đùi -  so với motor háng mô phỏng -->
        </xacro:if>
        <xacro:if value="${(side == 'right')}">
          <origin xyz="0.005 -0.055 -0.05" rpy="0 0 0"/>
          <!-- Vị trí đặt link đùi -  so với motor háng mô phỏng -->
        </xacro:if>
        <geometry>
          <cylinder radius="0.01" length="0.1"/>
        </geometry>
        <material name="green"/>
      </visual>
      <collision name="${prefix}_knee_collision">
        <geometry>
          <cylinder radius="0.01" length="0.1"/>
        </geometry>
      </collision>
      <inertial>
        <mass value="0.5"/>
        <inertia ixx="0.000417" ixy="0.0" ixz="0.0" iyy="0.000417" iyz="0.0" izz="0.000833"/>
      </inertial>
    </link>

    <!-- knee Joint (Đùi, quay về sau ) -->
    <joint name="${prefix}_knee_joint" type="revolute">
      <parent link="${prefix}_hip_motor_link"/>
      <!-- Gắn vào motor háng mô phỏng -->
      <child link="${prefix}_knee_link"/>
      <origin xyz="0 0 0" rpy="0 0.5 0"/>
      <axis xyz="0 1 0"/>
      <limit lower="-1.57" upper="1.57" effort="30" velocity="7.0"/>
    </joint>

    <!-- x2.1 Motor link vỏ motor mô phỏng Đầu gối , không quay -->
    <link name="${prefix}_knee_motor_link">
      <visual name="${prefix}_knee_motor_visual">
        <geometry>
          <cylinder radius="0.015" length="0.02"/>
        </geometry>
        <xacro:if value="${(side == 'left')}">
          <origin xyz="0.01 0.055 -0.085" rpy="1.0 0 0"/>
          <!-- vị trí đặt link mô phỏng motor khớp háng- trái -->
        </xacro:if>
        <xacro:if value="${(side == 'right')}">
          <origin xyz="0.01 -0.055 -0.085" rpy="1.0 0 0"/>
          <!-- vị trí đặt link mô phỏng motor khớp háng- phải -->
        </xacro:if>
        <material name="red"/>
      </visual>
     <inertial>
        <mass value="0.5"/>
        <inertia ixx="0.000417" ixy="0.0" ixz="0.0" iyy="0.000417" iyz="0.0" izz="0.000833"/>
      </inertial>
    </link>

    <!-- x2.2 Gắn motor link mô phỏng vào body bằng joint cố định -->
    <joint name="${prefix}_knee_motor_fixed" type="fixed">
      <parent link="${prefix}_knee_link"/>
      <child link="${prefix}_knee_motor_link"/>
      <origin xyz="0 0 -0.01" rpy="0 0 0"/>
      <!-- Vị trí gắn motor -->
    </joint>


    <!-- *** Kết thúc phần đùi chân *** -->


    <!-- *** Bắt đầu phần cẳng chân *** -->

    <!-- ankle Link -->
    <link name="${prefix}_ankle_link">
      <visual name="${prefix}_ankle_visual">
        <geometry>
          <cylinder radius="0.01" length="0.1"/>
        </geometry>
        <xacro:if value="${(side == 'left')}">
          <origin xyz="0 0 -0.08" rpy="0 -1.0 0"/>
          <!-- Dịch xuống 1/2 chiều dài -->
          <!-- vị trí đặt link mô phỏng motor khớp háng- trái -->
        </xacro:if>
        <xacro:if value="${(side == 'right')}">
          <origin xyz="0 0 -0.08" rpy="0 -1.0 0"/>
          <!-- Dịch xuống 1/2 chiều dài -->
          <!-- vị trí đặt link mô phỏng motor khớp háng- phải -->
        </xacro:if>
        <material name="purple"/>
      </visual>
      <collision name="${prefix}_ankle_collision">
        <origin xyz="0 0 -0.08"/>
        <!-- Khớp visual -->
        <geometry>
          <cylinder radius="0.01" length="0.1"/>
        </geometry>
      </collision>
      <inertial>
        <origin xyz="0 0 -0.08"/>
        <!-- Dịch khối lượng xuống luôn -->
        <mass value="0.2"/>
        <inertia ixx="0.000417" ixy="0.0" ixz="0.0" iyy="0.000417" iyz="0.0" izz="0.000833"/>
      </inertial>
    </link>

    <!-- ankle Joint (Cẳng chân, quay về trước 45°) -->
    <joint name="${prefix}_ankle_joint" type="fixed">
      <parent link="${prefix}_knee_motor_link"/>
      <child link="${prefix}_ankle_link"/>
      <xacro:if value="${(side == 'left')}">
        <origin xyz="0 0.055 0" rpy="0 -0.60 0"/>
        <!-- Vị trí đặt link đùi -  so với motor háng mô phỏng -->
      </xacro:if>
      <xacro:if value="${(side == 'right')}">
        <origin xyz="0 -0.055 0" rpy="0 -0.60 0"/>
        <!-- Vị trí đặt link đùi -  so với motor háng mô phỏng -->
      </xacro:if>
      <!-- rút ngắn chiều dài -->
      <axis xyz="0 1 0"/>
      <limit lower="-1.57" upper="1.57" effort="30" velocity="7.0"/>
    </joint>



    <!-- *** Kết thúc phần cẳng chân *** -->

    <!-- Foot Link -->
    <link name="${prefix}_foot_link">
      <visual name="${prefix}_foot_visual">
        <origin xyz="0.045 0 -0.055"/>
        <geometry>
          <sphere radius="0.02"/>
        </geometry>
        <material name="black"/>
      </visual>
      <collision name="${prefix}_foot_collision">
        <origin xyz="0.045 0 -0.055"/>
        <geometry>
          <sphere radius="0.02"/>
        </geometry>
      </collision>
      <inertial>
        <mass value="0.05"/>
        <inertia ixx="0.000417" ixy="0.0" ixz="0.0" iyy="0.000417" iyz="0.0" izz="0.000833"/>
      </inertial>
    </link>

    <!-- Foot Joint -->
    <joint name="${prefix}_foot_joint" type="fixed">
      <parent link="${prefix}_ankle_link"/>
      <child link="${prefix}_foot_link"/>
      <origin xyz="0 0 -0.05" rpy="0 0 0"/>
      <!-- rút gọn lại -->
    </joint>


    <!-- Transmission cho các joint -->
    <transmission name="${prefix}_knee_trans">
      <type>transmission_interface/SimpleTransmission</type>
      <joint name="${prefix}_knee_joint"/>
      <actuator name="${prefix}_knee_motor">
        <mechanical_reduction>1</mechanical_reduction>
      </actuator>
    </transmission>

    <transmission name="${prefix}_ankle_trans">
      <type>transmission_interface/SimpleTransmission</type>
      <joint name="${prefix}_ankle_joint"/>
      <actuator name="${prefix}_ankle_motor">
        <mechanical_reduction>1</mechanical_reduction>
      </actuator>
    </transmission>
  </xacro:macro>

</robot>