<?xml version="1.0" ?>
<!-- =================================================================================== -->
<!-- |    This document was autogenerated by xacro from first_robot/description/robot.urdf.xacro | -->
<!-- |    EDITING THIS FILE BY HAND IS NOT RECOMMENDED                                 | -->
<!-- =================================================================================== -->
<robot name="my_robot">
  <!-- Specify some standard inertial calculations https://en.wikipedia.org/wiki/List_of_moments_of_inertia -->
  <!-- These make use of xacro's mathematical functionality -->
  <material name="white">
    <color rgba="1 1 1 1"/>
  </material>
  <material name="orange">
    <color rgba="1 0.3 0.1 1"/>
  </material>
  <material name="blue">
    <color rgba="0.2 0.2 1 1"/>
  </material>
  <material name="black">
    <color rgba="0 0 0 1"/>
  </material>
  <material name="red">
    <color rgba="1 0 0 1"/>
  </material>
  <material name="grey">
    <color rgba="0.5 0.5 0.5 1"/>
  </material>
  <!-- BASE LINK -->
  <link name="base_link">
    <inertial>
      <mass value="0.5"/>
      <!-- Giảm từ 2.0 -->
      <origin xyz="0 0 0.1"/>
      <inertia ixx="0.1" ixy="0" ixz="0" iyy="0.1" iyz="0" izz="0.1"/>
    </inertial>
  </link>
  <!-- CHASSIS LINK -->
  <joint name="chassis_joint" type="fixed">
    <parent link="base_link"/>
    <child link="chassis"/>
    <origin xyz="0 0 0"/>
  </joint>
  <link name="chassis">
    <visual>
      <origin xyz="0 0 0.075"/>
      <geometry>
        <box size="0.5 0.2 0.15"/>
      </geometry>
      <material name="white"/>
    </visual>
    <collision>
      <origin xyz="0.15 0 0.075"/>
      <geometry>
        <box size="0.5 0.2 0.15"/>
      </geometry>
    </collision>
    <inertial>
      <origin rpy="0 0 0" xyz="0 0 0.075"/>
      <mass value="0.5"/>
      <inertia ixx="0.0026041666666666665" ixy="0.0" ixz="0.0" iyy="0.011354166666666667" iyz="0.0" izz="0.012083333333333335"/>
    </inertial>
  </link>
  <!-- Hip Motor Link -->
  <link name="left_front_hip_motor_link">
    <visual>
      <origin xyz="0 0 0.02"/>
      <geometry>
        <cylinder length="0.02" radius="0.015"/>
      </geometry>
      <material name="grey"/>
    </visual>
    <collision>
      <origin xyz="0 0 0.02"/>
      <geometry>
        <cylinder length="0.02" radius="0.015"/>
      </geometry>
    </collision>
    <inertial>
      <mass value="0.05"/>
      <inertia ixx="0.00001" ixy="0.0" ixz="0.0" iyy="0.00001" iyz="0.0" izz="0.00001"/>
    </inertial>
  </link>
  <!-- Fixed joint gắn hip motor vào chassis -->
  <joint name="left_front_hip_motor_fixed" type="fixed">
    <parent link="chassis"/>
    <child link="left_front_hip_motor_link"/>
    <origin xyz="0.15 0.1 0.075"/>
  </joint>
  <!-- Hip Joint -->
  <joint name="left_front_hip_joint" type="revolute">
    <parent link="left_front_hip_motor_link"/>
    <child link="left_front_thigh"/>
    <origin xyz="0 0 0"/>
    <axis xyz="0 1 0"/>
    <limit effort="5" lower="-1.57" upper="1.57" velocity="2.0"/>
  </joint>
  <!-- Thigh Link -->
  <link name="left_front_thigh">
    <visual>
      <origin xyz="0 0 -0.075"/>
      <geometry>
        <box size="0.05 0.05 0.15"/>
      </geometry>
      <material name="blue"/>
    </visual>
    <collision>
      <origin xyz="0 0 -0.075"/>
      <geometry>
        <box size="0.05 0.05 0.15"/>
      </geometry>
    </collision>
    <inertial>
      <mass value="0.2"/>
      <origin rpy="0 0 0" xyz="0 0 0"/>
      <inertia ixx="0.0004166666666666667" ixy="0.0" ixz="0.0" iyy="0.0004166666666666667" iyz="0.0" izz="8.333333333333334e-05"/>
    </inertial>
  </link>
  <!-- Knee Motor Link -->
  <link name="left_front_knee_motor_link">
    <visual>
      <origin xyz="0 0 -0.01"/>
      <geometry>
        <cylinder length="0.02" radius="0.012"/>
      </geometry>
      <material name="grey"/>
    </visual>
    <collision>
      <origin xyz="0 0 -0.01"/>
      <geometry>
        <cylinder length="0.02" radius="0.012"/>
      </geometry>
    </collision>
    <inertial>
      <mass value="0.03"/>
      <inertia ixx="0.00001" ixy="0.0" ixz="0.0" iyy="0.00001" iyz="0.0" izz="0.00001"/>
    </inertial>
  </link>
  <!-- Fixed joint gắn knee motor vào thigh -->
  <joint name="left_front_knee_motor_fixed" type="fixed">
    <parent link="left_front_thigh"/>
    <child link="left_front_knee_motor_link"/>
    <origin xyz="0 0 -0.15"/>
  </joint>
  <!-- Knee Joint -->
  <joint name="left_front_upper_leg_joint" type="revolute">
    <parent link="left_front_knee_motor_link"/>
    <child link="left_front_shank"/>
    <origin xyz="0 0 0"/>
    <axis xyz="0 1 0"/>
    <limit effort="5" lower="-1.57" upper="1.57" velocity="2.0"/>
  </joint>
  <!-- Shank Link -->
  <link name="left_front_shank">
    <visual>
      <origin xyz="0 0 -0.075"/>
      <geometry>
        <box size="0.04 0.04 0.15"/>
      </geometry>
      <material name="red"/>
    </visual>
    <collision>
      <origin xyz="0 0 -0.075"/>
      <geometry>
        <box size="0.04 0.04 0.15"/>
      </geometry>
    </collision>
    <inertial>
      <mass value="0.2"/>
      <origin rpy="0 0 0" xyz="0 0 0"/>
      <inertia ixx="0.00040166666666666665" ixy="0.0" ixz="0.0" iyy="0.00040166666666666665" iyz="0.0" izz="5.333333333333333e-05"/>
    </inertial>
  </link>
  <!-- Ankle Motor Link -->
  <link name="left_front_ankle_motor_link">
    <visual>
      <origin xyz="0 0 -0.01"/>
      <geometry>
        <cylinder length="0.02" radius="0.012"/>
      </geometry>
      <material name="grey"/>
    </visual>
    <collision>
      <origin xyz="0 0 -0.01"/>
      <geometry>
        <cylinder length="0.02" radius="0.012"/>
      </geometry>
    </collision>
    <inertial>
      <mass value="0.03"/>
      <inertia ixx="0.00001" ixy="0.0" ixz="0.0" iyy="0.00001" iyz="0.0" izz="0.00001"/>
    </inertial>
  </link>
  <!-- Fixed joint gắn ankle motor vào shank -->
  <joint name="left_front_ankle_motor_fixed" type="fixed">
    <parent link="left_front_shank"/>
    <child link="left_front_ankle_motor_link"/>
    <origin xyz="0 0 -0.15"/>
  </joint>
  <!-- Ankle Joint -->
  <joint name="left_front_lower_leg_joint" type="revolute">
    <parent link="left_front_ankle_motor_link"/>
    <child link="left_front_foot"/>
    <origin xyz="0 0 0"/>
    <axis xyz="0 1 0"/>
    <limit effort="5" lower="-1.57" upper="1.57" velocity="2.0"/>
  </joint>
  <!-- Foot Link -->
  <link name="left_front_foot">
    <visual>
      <geometry>
        <sphere radius="0.03"/>
      </geometry>
      <material name="black"/>
    </visual>
    <collision>
      <geometry>
        <sphere radius="0.03"/>
      </geometry>
    </collision>
    <inertial>
      <origin rpy="0 0 0" xyz="0 0 0"/>
      <mass value="0.1"/>
      <inertia ixx="3.600000000000001e-05" ixy="0.0" ixz="0.0" iyy="3.600000000000001e-05" iyz="0.0" izz="3.600000000000001e-05"/>
    </inertial>
  </link>
  <transmission name="left_front_hip_trans">
    <type>transmission_interface/SimpleTransmission</type>
    <joint name="left_front_hip_joint">
      <hardwareInterface>hardware_interface/PositionJointInterface</hardwareInterface>
    </joint>
    <actuator name="left_front_hip_motor">
      <hardwareInterface>hardware_interface/PositionJointInterface</hardwareInterface>
      <mechanicalReduction>1</mechanicalReduction>
    </actuator>
  </transmission>
  <transmission name="left_front_knee_trans">
    <type>transmission_interface/SimpleTransmission</type>
    <joint name="left_front_upper_leg_joint">
      <hardwareInterface>hardware_interface/PositionJointInterface</hardwareInterface>
    </joint>
    <actuator name="left_front_knee_motor">
      <hardwareInterface>hardware_interface/PositionJointInterface</hardwareInterface>
      <mechanicalReduction>1</mechanicalReduction>
    </actuator>
  </transmission>
  <transmission name="left_front_ankle_trans">
    <type>transmission_interface/SimpleTransmission</type>
    <joint name="left_front_lower_leg_joint">
      <hardwareInterface>hardware_interface/PositionJointInterface</hardwareInterface>
    </joint>
    <actuator name="left_front_ankle_motor">
      <hardwareInterface>hardware_interface/PositionJointInterface</hardwareInterface>
      <mechanicalReduction>1</mechanicalReduction>
    </actuator>
  </transmission>
  <transmission name="right_front_hip_trans">
    <type>transmission_interface/SimpleTransmission</type>
    <joint name="right_front_hip_joint">
      <hardwareInterface>hardware_interface/PositionJointInterface</hardwareInterface>
    </joint>
    <actuator name="right_front_hip_motor">
      <hardwareInterface>hardware_interface/PositionJointInterface</hardwareInterface>
      <mechanicalReduction>1</mechanicalReduction>
    </actuator>
  </transmission>
  <transmission name="right_front_knee_trans">
    <type>transmission_interface/SimpleTransmission</type>
    <joint name="right_front_upper_leg_joint">
      <hardwareInterface>hardware_interface/PositionJointInterface</hardwareInterface>
    </joint>
    <actuator name="right_front_knee_motor">
      <hardwareInterface>hardware_interface/PositionJointInterface</hardwareInterface>
      <mechanicalReduction>1</mechanicalReduction>
    </actuator>
  </transmission>
  <transmission name="right_front_ankle_trans">
    <type>transmission_interface/SimpleTransmission</type>
    <joint name="right_front_lower_leg_joint">
      <hardwareInterface>hardware_interface/PositionJointInterface</hardwareInterface>
    </joint>
    <actuator name="right_front_ankle_motor">
      <hardwareInterface>hardware_interface/PositionJointInterface</hardwareInterface>
      <mechanicalReduction>1</mechanicalReduction>
    </actuator>
  </transmission>
  <transmission name="left_rear_hip_trans">
    <type>transmission_interface/SimpleTransmission</type>
    <joint name="left_rear_hip_joint">
      <hardwareInterface>hardware_interface/PositionJointInterface</hardwareInterface>
    </joint>
    <actuator name="left_rear_hip_motor">
      <hardwareInterface>hardware_interface/PositionJointInterface</hardwareInterface>
      <mechanicalReduction>1</mechanicalReduction>
    </actuator>
  </transmission>
  <transmission name="left_rear_knee_trans">
    <type>transmission_interface/SimpleTransmission</type>
    <joint name="left_rear_upper_leg_joint">
      <hardwareInterface>hardware_interface/PositionJointInterface</hardwareInterface>
    </joint>
    <actuator name="left_rear_knee_motor">
      <hardwareInterface>hardware_interface/PositionJointInterface</hardwareInterface>
      <mechanicalReduction>1</mechanicalReduction>
    </actuator>
  </transmission>
  <transmission name="left_rear_ankle_trans">
    <type>transmission_interface/SimpleTransmission</type>
    <joint name="left_rear_lower_leg_joint">
      <hardwareInterface>hardware_interface/PositionJointInterface</hardwareInterface>
    </joint>
    <actuator name="left_rear_ankle_motor">
      <hardwareInterface>hardware_interface/PositionJointInterface</hardwareInterface>
      <mechanicalReduction>1</mechanicalReduction>
    </actuator>
  </transmission>
  <transmission name="right_rear_hip_trans">
    <type>transmission_interface/SimpleTransmission</type>
    <joint name="right_rear_hip_joint">
      <hardwareInterface>hardware_interface/PositionJointInterface</hardwareInterface>
    </joint>
    <actuator name="right_rear_hip_motor">
      <hardwareInterface>hardware_interface/PositionJointInterface</hardwareInterface>
      <mechanicalReduction>1</mechanicalReduction>
    </actuator>
  </transmission>
  <transmission name="right_rear_knee_trans">
    <type>transmission_interface/SimpleTransmission</type>
    <joint name="right_rear_upper_leg_joint">
      <hardwareInterface>hardware_interface/PositionJointInterface</hardwareInterface>
    </joint>
    <actuator name="right_rear_knee_motor">
      <hardwareInterface>hardware_interface/PositionJointInterface</hardwareInterface>
      <mechanicalReduction>1</mechanicalReduction>
    </actuator>
  </transmission>
  <transmission name="right_rear_ankle_trans">
    <type>transmission_interface/SimpleTransmission</type>
    <joint name="right_rear_lower_leg_joint">
      <hardwareInterface>hardware_interface/PositionJointInterface</hardwareInterface>
    </joint>
    <actuator name="right_rear_ankle_motor">
      <hardwareInterface>hardware_interface/PositionJointInterface</hardwareInterface>
      <mechanicalReduction>1</mechanicalReduction>
    </actuator>
  </transmission>
  <!-- Hip Motor Link -->
  <link name="right_front_hip_motor_link">
    <visual>
      <origin xyz="0 0 0.02"/>
      <geometry>
        <cylinder length="0.02" radius="0.015"/>
      </geometry>
      <material name="grey"/>
    </visual>
    <collision>
      <origin xyz="0 0 0.02"/>
      <geometry>
        <cylinder length="0.02" radius="0.015"/>
      </geometry>
    </collision>
    <inertial>
      <mass value="0.05"/>
      <inertia ixx="0.00001" ixy="0.0" ixz="0.0" iyy="0.00001" iyz="0.0" izz="0.00001"/>
    </inertial>
  </link>
  <!-- Fixed joint gắn hip motor vào chassis -->
  <joint name="right_front_hip_motor_fixed" type="fixed">
    <parent link="chassis"/>
    <child link="right_front_hip_motor_link"/>
    <origin xyz="0.15 -0.1 0.075"/>
  </joint>
  <!-- Hip Joint -->
  <joint name="right_front_hip_joint" type="revolute">
    <parent link="right_front_hip_motor_link"/>
    <child link="right_front_thigh"/>
    <origin xyz="0 0 0"/>
    <axis xyz="0 1 0"/>
    <limit effort="5" lower="-1.57" upper="1.57" velocity="2.0"/>
  </joint>
  <!-- Thigh Link -->
  <link name="right_front_thigh">
    <visual>
      <origin xyz="0 0 -0.075"/>
      <geometry>
        <box size="0.05 0.05 0.15"/>
      </geometry>
      <material name="blue"/>
    </visual>
    <collision>
      <origin xyz="0 0 -0.075"/>
      <geometry>
        <box size="0.05 0.05 0.15"/>
      </geometry>
    </collision>
    <inertial>
      <mass value="0.2"/>
      <origin rpy="0 0 0" xyz="0 0 0"/>
      <inertia ixx="0.0004166666666666667" ixy="0.0" ixz="0.0" iyy="0.0004166666666666667" iyz="0.0" izz="8.333333333333334e-05"/>
    </inertial>
  </link>
  <!-- Knee Motor Link -->
  <link name="right_front_knee_motor_link">
    <visual>
      <origin xyz="0 0 -0.01"/>
      <geometry>
        <cylinder length="0.02" radius="0.012"/>
      </geometry>
      <material name="grey"/>
    </visual>
    <collision>
      <origin xyz="0 0 -0.01"/>
      <geometry>
        <cylinder length="0.02" radius="0.012"/>
      </geometry>
    </collision>
    <inertial>
      <mass value="0.03"/>
      <inertia ixx="0.00001" ixy="0.0" ixz="0.0" iyy="0.00001" iyz="0.0" izz="0.00001"/>
    </inertial>
  </link>
  <!-- Fixed joint gắn knee motor vào thigh -->
  <joint name="right_front_knee_motor_fixed" type="fixed">
    <parent link="right_front_thigh"/>
    <child link="right_front_knee_motor_link"/>
    <origin xyz="0 0 -0.15"/>
  </joint>
  <!-- Knee Joint -->
  <joint name="right_front_upper_leg_joint" type="revolute">
    <parent link="right_front_knee_motor_link"/>
    <child link="right_front_shank"/>
    <origin xyz="0 0 0"/>
    <axis xyz="0 1 0"/>
    <limit effort="5" lower="-1.57" upper="1.57" velocity="2.0"/>
  </joint>
  <!-- Shank Link -->
  <link name="right_front_shank">
    <visual>
      <origin xyz="0 0 -0.075"/>
      <geometry>
        <box size="0.04 0.04 0.15"/>
      </geometry>
      <material name="red"/>
    </visual>
    <collision>
      <origin xyz="0 0 -0.075"/>
      <geometry>
        <box size="0.04 0.04 0.15"/>
      </geometry>
    </collision>
    <inertial>
      <mass value="0.2"/>
      <origin rpy="0 0 0" xyz="0 0 0"/>
      <inertia ixx="0.00040166666666666665" ixy="0.0" ixz="0.0" iyy="0.00040166666666666665" iyz="0.0" izz="5.333333333333333e-05"/>
    </inertial>
  </link>
  <!-- Ankle Motor Link -->
  <link name="right_front_ankle_motor_link">
    <visual>
      <origin xyz="0 0 -0.01"/>
      <geometry>
        <cylinder length="0.02" radius="0.012"/>
      </geometry>
      <material name="grey"/>
    </visual>
    <collision>
      <origin xyz="0 0 -0.01"/>
      <geometry>
        <cylinder length="0.02" radius="0.012"/>
      </geometry>
    </collision>
    <inertial>
      <mass value="0.03"/>
      <inertia ixx="0.00001" ixy="0.0" ixz="0.0" iyy="0.00001" iyz="0.0" izz="0.00001"/>
    </inertial>
  </link>
  <!-- Fixed joint gắn ankle motor vào shank -->
  <joint name="right_front_ankle_motor_fixed" type="fixed">
    <parent link="right_front_shank"/>
    <child link="right_front_ankle_motor_link"/>
    <origin xyz="0 0 -0.15"/>
  </joint>
  <!-- Ankle Joint -->
  <joint name="right_front_lower_leg_joint" type="revolute">
    <parent link="right_front_ankle_motor_link"/>
    <child link="right_front_foot"/>
    <origin xyz="0 0 0"/>
    <axis xyz="0 1 0"/>
    <limit effort="5" lower="-1.57" upper="1.57" velocity="2.0"/>
  </joint>
  <!-- Foot Link -->
  <link name="right_front_foot">
    <visual>
      <geometry>
        <sphere radius="0.03"/>
      </geometry>
      <material name="black"/>
    </visual>
    <collision>
      <geometry>
        <sphere radius="0.03"/>
      </geometry>
    </collision>
    <inertial>
      <origin rpy="0 0 0" xyz="0 0 0"/>
      <mass value="0.1"/>
      <inertia ixx="3.600000000000001e-05" ixy="0.0" ixz="0.0" iyy="3.600000000000001e-05" iyz="0.0" izz="3.600000000000001e-05"/>
    </inertial>
  </link>
  <transmission name="left_front_hip_trans">
    <type>transmission_interface/SimpleTransmission</type>
    <joint name="left_front_hip_joint">
      <hardwareInterface>hardware_interface/PositionJointInterface</hardwareInterface>
    </joint>
    <actuator name="left_front_hip_motor">
      <hardwareInterface>hardware_interface/PositionJointInterface</hardwareInterface>
      <mechanicalReduction>1</mechanicalReduction>
    </actuator>
  </transmission>
  <transmission name="left_front_knee_trans">
    <type>transmission_interface/SimpleTransmission</type>
    <joint name="left_front_upper_leg_joint">
      <hardwareInterface>hardware_interface/PositionJointInterface</hardwareInterface>
    </joint>
    <actuator name="left_front_knee_motor">
      <hardwareInterface>hardware_interface/PositionJointInterface</hardwareInterface>
      <mechanicalReduction>1</mechanicalReduction>
    </actuator>
  </transmission>
  <transmission name="left_front_ankle_trans">
    <type>transmission_interface/SimpleTransmission</type>
    <joint name="left_front_lower_leg_joint">
      <hardwareInterface>hardware_interface/PositionJointInterface</hardwareInterface>
    </joint>
    <actuator name="left_front_ankle_motor">
      <hardwareInterface>hardware_interface/PositionJointInterface</hardwareInterface>
      <mechanicalReduction>1</mechanicalReduction>
    </actuator>
  </transmission>
  <transmission name="right_front_hip_trans">
    <type>transmission_interface/SimpleTransmission</type>
    <joint name="right_front_hip_joint">
      <hardwareInterface>hardware_interface/PositionJointInterface</hardwareInterface>
    </joint>
    <actuator name="right_front_hip_motor">
      <hardwareInterface>hardware_interface/PositionJointInterface</hardwareInterface>
      <mechanicalReduction>1</mechanicalReduction>
    </actuator>
  </transmission>
  <transmission name="right_front_knee_trans">
    <type>transmission_interface/SimpleTransmission</type>
    <joint name="right_front_upper_leg_joint">
      <hardwareInterface>hardware_interface/PositionJointInterface</hardwareInterface>
    </joint>
    <actuator name="right_front_knee_motor">
      <hardwareInterface>hardware_interface/PositionJointInterface</hardwareInterface>
      <mechanicalReduction>1</mechanicalReduction>
    </actuator>
  </transmission>
  <transmission name="right_front_ankle_trans">
    <type>transmission_interface/SimpleTransmission</type>
    <joint name="right_front_lower_leg_joint">
      <hardwareInterface>hardware_interface/PositionJointInterface</hardwareInterface>
    </joint>
    <actuator name="right_front_ankle_motor">
      <hardwareInterface>hardware_interface/PositionJointInterface</hardwareInterface>
      <mechanicalReduction>1</mechanicalReduction>
    </actuator>
  </transmission>
  <transmission name="left_rear_hip_trans">
    <type>transmission_interface/SimpleTransmission</type>
    <joint name="left_rear_hip_joint">
      <hardwareInterface>hardware_interface/PositionJointInterface</hardwareInterface>
    </joint>
    <actuator name="left_rear_hip_motor">
      <hardwareInterface>hardware_interface/PositionJointInterface</hardwareInterface>
      <mechanicalReduction>1</mechanicalReduction>
    </actuator>
  </transmission>
  <transmission name="left_rear_knee_trans">
    <type>transmission_interface/SimpleTransmission</type>
    <joint name="left_rear_upper_leg_joint">
      <hardwareInterface>hardware_interface/PositionJointInterface</hardwareInterface>
    </joint>
    <actuator name="left_rear_knee_motor">
      <hardwareInterface>hardware_interface/PositionJointInterface</hardwareInterface>
      <mechanicalReduction>1</mechanicalReduction>
    </actuator>
  </transmission>
  <transmission name="left_rear_ankle_trans">
    <type>transmission_interface/SimpleTransmission</type>
    <joint name="left_rear_lower_leg_joint">
      <hardwareInterface>hardware_interface/PositionJointInterface</hardwareInterface>
    </joint>
    <actuator name="left_rear_ankle_motor">
      <hardwareInterface>hardware_interface/PositionJointInterface</hardwareInterface>
      <mechanicalReduction>1</mechanicalReduction>
    </actuator>
  </transmission>
  <transmission name="right_rear_hip_trans">
    <type>transmission_interface/SimpleTransmission</type>
    <joint name="right_rear_hip_joint">
      <hardwareInterface>hardware_interface/PositionJointInterface</hardwareInterface>
    </joint>
    <actuator name="right_rear_hip_motor">
      <hardwareInterface>hardware_interface/PositionJointInterface</hardwareInterface>
      <mechanicalReduction>1</mechanicalReduction>
    </actuator>
  </transmission>
  <transmission name="right_rear_knee_trans">
    <type>transmission_interface/SimpleTransmission</type>
    <joint name="right_rear_upper_leg_joint">
      <hardwareInterface>hardware_interface/PositionJointInterface</hardwareInterface>
    </joint>
    <actuator name="right_rear_knee_motor">
      <hardwareInterface>hardware_interface/PositionJointInterface</hardwareInterface>
      <mechanicalReduction>1</mechanicalReduction>
    </actuator>
  </transmission>
  <transmission name="right_rear_ankle_trans">
    <type>transmission_interface/SimpleTransmission</type>
    <joint name="right_rear_lower_leg_joint">
      <hardwareInterface>hardware_interface/PositionJointInterface</hardwareInterface>
    </joint>
    <actuator name="right_rear_ankle_motor">
      <hardwareInterface>hardware_interface/PositionJointInterface</hardwareInterface>
      <mechanicalReduction>1</mechanicalReduction>
    </actuator>
  </transmission>
  <!-- Hip Motor Link -->
  <link name="left_rear_hip_motor_link">
    <visual>
      <origin xyz="0 0 0.02"/>
      <geometry>
        <cylinder length="0.02" radius="0.015"/>
      </geometry>
      <material name="grey"/>
    </visual>
    <collision>
      <origin xyz="0 0 0.02"/>
      <geometry>
        <cylinder length="0.02" radius="0.015"/>
      </geometry>
    </collision>
    <inertial>
      <mass value="0.05"/>
      <inertia ixx="0.00001" ixy="0.0" ixz="0.0" iyy="0.00001" iyz="0.0" izz="0.00001"/>
    </inertial>
  </link>
  <!-- Fixed joint gắn hip motor vào chassis -->
  <joint name="left_rear_hip_motor_fixed" type="fixed">
    <parent link="chassis"/>
    <child link="left_rear_hip_motor_link"/>
    <origin xyz="-0.15 0.1 0.075"/>
  </joint>
  <!-- Hip Joint -->
  <joint name="left_rear_hip_joint" type="revolute">
    <parent link="left_rear_hip_motor_link"/>
    <child link="left_rear_thigh"/>
    <origin xyz="0 0 0"/>
    <axis xyz="0 1 0"/>
    <limit effort="5" lower="-1.57" upper="1.57" velocity="2.0"/>
  </joint>
  <!-- Thigh Link -->
  <link name="left_rear_thigh">
    <visual>
      <origin xyz="0 0 -0.075"/>
      <geometry>
        <box size="0.05 0.05 0.15"/>
      </geometry>
      <material name="blue"/>
    </visual>
    <collision>
      <origin xyz="0 0 -0.075"/>
      <geometry>
        <box size="0.05 0.05 0.15"/>
      </geometry>
    </collision>
    <inertial>
      <mass value="0.2"/>
      <origin rpy="0 0 0" xyz="0 0 0"/>
      <inertia ixx="0.0004166666666666667" ixy="0.0" ixz="0.0" iyy="0.0004166666666666667" iyz="0.0" izz="8.333333333333334e-05"/>
    </inertial>
  </link>
  <!-- Knee Motor Link -->
  <link name="left_rear_knee_motor_link">
    <visual>
      <origin xyz="0 0 -0.01"/>
      <geometry>
        <cylinder length="0.02" radius="0.012"/>
      </geometry>
      <material name="grey"/>
    </visual>
    <collision>
      <origin xyz="0 0 -0.01"/>
      <geometry>
        <cylinder length="0.02" radius="0.012"/>
      </geometry>
    </collision>
    <inertial>
      <mass value="0.03"/>
      <inertia ixx="0.00001" ixy="0.0" ixz="0.0" iyy="0.00001" iyz="0.0" izz="0.00001"/>
    </inertial>
  </link>
  <!-- Fixed joint gắn knee motor vào thigh -->
  <joint name="left_rear_knee_motor_fixed" type="fixed">
    <parent link="left_rear_thigh"/>
    <child link="left_rear_knee_motor_link"/>
    <origin xyz="0 0 -0.15"/>
  </joint>
  <!-- Knee Joint -->
  <joint name="left_rear_upper_leg_joint" type="revolute">
    <parent link="left_rear_knee_motor_link"/>
    <child link="left_rear_shank"/>
    <origin xyz="0 0 0"/>
    <axis xyz="0 1 0"/>
    <limit effort="5" lower="-1.57" upper="1.57" velocity="2.0"/>
  </joint>
  <!-- Shank Link -->
  <link name="left_rear_shank">
    <visual>
      <origin xyz="0 0 -0.075"/>
      <geometry>
        <box size="0.04 0.04 0.15"/>
      </geometry>
      <material name="red"/>
    </visual>
    <collision>
      <origin xyz="0 0 -0.075"/>
      <geometry>
        <box size="0.04 0.04 0.15"/>
      </geometry>
    </collision>
    <inertial>
      <mass value="0.2"/>
      <origin rpy="0 0 0" xyz="0 0 0"/>
      <inertia ixx="0.00040166666666666665" ixy="0.0" ixz="0.0" iyy="0.00040166666666666665" iyz="0.0" izz="5.333333333333333e-05"/>
    </inertial>
  </link>
  <!-- Ankle Motor Link -->
  <link name="left_rear_ankle_motor_link">
    <visual>
      <origin xyz="0 0 -0.01"/>
      <geometry>
        <cylinder length="0.02" radius="0.012"/>
      </geometry>
      <material name="grey"/>
    </visual>
    <collision>
      <origin xyz="0 0 -0.01"/>
      <geometry>
        <cylinder length="0.02" radius="0.012"/>
      </geometry>
    </collision>
    <inertial>
      <mass value="0.03"/>
      <inertia ixx="0.00001" ixy="0.0" ixz="0.0" iyy="0.00001" iyz="0.0" izz="0.00001"/>
    </inertial>
  </link>
  <!-- Fixed joint gắn ankle motor vào shank -->
  <joint name="left_rear_ankle_motor_fixed" type="fixed">
    <parent link="left_rear_shank"/>
    <child link="left_rear_ankle_motor_link"/>
    <origin xyz="0 0 -0.15"/>
  </joint>
  <!-- Ankle Joint -->
  <joint name="left_rear_lower_leg_joint" type="revolute">
    <parent link="left_rear_ankle_motor_link"/>
    <child link="left_rear_foot"/>
    <origin xyz="0 0 0"/>
    <axis xyz="0 1 0"/>
    <limit effort="5" lower="-1.57" upper="1.57" velocity="2.0"/>
  </joint>
  <!-- Foot Link -->
  <link name="left_rear_foot">
    <visual>
      <geometry>
        <sphere radius="0.03"/>
      </geometry>
      <material name="black"/>
    </visual>
    <collision>
      <geometry>
        <sphere radius="0.03"/>
      </geometry>
    </collision>
    <inertial>
      <origin rpy="0 0 0" xyz="0 0 0"/>
      <mass value="0.1"/>
      <inertia ixx="3.600000000000001e-05" ixy="0.0" ixz="0.0" iyy="3.600000000000001e-05" iyz="0.0" izz="3.600000000000001e-05"/>
    </inertial>
  </link>
  <transmission name="left_front_hip_trans">
    <type>transmission_interface/SimpleTransmission</type>
    <joint name="left_front_hip_joint">
      <hardwareInterface>hardware_interface/PositionJointInterface</hardwareInterface>
    </joint>
    <actuator name="left_front_hip_motor">
      <hardwareInterface>hardware_interface/PositionJointInterface</hardwareInterface>
      <mechanicalReduction>1</mechanicalReduction>
    </actuator>
  </transmission>
  <transmission name="left_front_knee_trans">
    <type>transmission_interface/SimpleTransmission</type>
    <joint name="left_front_upper_leg_joint">
      <hardwareInterface>hardware_interface/PositionJointInterface</hardwareInterface>
    </joint>
    <actuator name="left_front_knee_motor">
      <hardwareInterface>hardware_interface/PositionJointInterface</hardwareInterface>
      <mechanicalReduction>1</mechanicalReduction>
    </actuator>
  </transmission>
  <transmission name="left_front_ankle_trans">
    <type>transmission_interface/SimpleTransmission</type>
    <joint name="left_front_lower_leg_joint">
      <hardwareInterface>hardware_interface/PositionJointInterface</hardwareInterface>
    </joint>
    <actuator name="left_front_ankle_motor">
      <hardwareInterface>hardware_interface/PositionJointInterface</hardwareInterface>
      <mechanicalReduction>1</mechanicalReduction>
    </actuator>
  </transmission>
  <transmission name="right_front_hip_trans">
    <type>transmission_interface/SimpleTransmission</type>
    <joint name="right_front_hip_joint">
      <hardwareInterface>hardware_interface/PositionJointInterface</hardwareInterface>
    </joint>
    <actuator name="right_front_hip_motor">
      <hardwareInterface>hardware_interface/PositionJointInterface</hardwareInterface>
      <mechanicalReduction>1</mechanicalReduction>
    </actuator>
  </transmission>
  <transmission name="right_front_knee_trans">
    <type>transmission_interface/SimpleTransmission</type>
    <joint name="right_front_upper_leg_joint">
      <hardwareInterface>hardware_interface/PositionJointInterface</hardwareInterface>
    </joint>
    <actuator name="right_front_knee_motor">
      <hardwareInterface>hardware_interface/PositionJointInterface</hardwareInterface>
      <mechanicalReduction>1</mechanicalReduction>
    </actuator>
  </transmission>
  <transmission name="right_front_ankle_trans">
    <type>transmission_interface/SimpleTransmission</type>
    <joint name="right_front_lower_leg_joint">
      <hardwareInterface>hardware_interface/PositionJointInterface</hardwareInterface>
    </joint>
    <actuator name="right_front_ankle_motor">
      <hardwareInterface>hardware_interface/PositionJointInterface</hardwareInterface>
      <mechanicalReduction>1</mechanicalReduction>
    </actuator>
  </transmission>
  <transmission name="left_rear_hip_trans">
    <type>transmission_interface/SimpleTransmission</type>
    <joint name="left_rear_hip_joint">
      <hardwareInterface>hardware_interface/PositionJointInterface</hardwareInterface>
    </joint>
    <actuator name="left_rear_hip_motor">
      <hardwareInterface>hardware_interface/PositionJointInterface</hardwareInterface>
      <mechanicalReduction>1</mechanicalReduction>
    </actuator>
  </transmission>
  <transmission name="left_rear_knee_trans">
    <type>transmission_interface/SimpleTransmission</type>
    <joint name="left_rear_upper_leg_joint">
      <hardwareInterface>hardware_interface/PositionJointInterface</hardwareInterface>
    </joint>
    <actuator name="left_rear_knee_motor">
      <hardwareInterface>hardware_interface/PositionJointInterface</hardwareInterface>
      <mechanicalReduction>1</mechanicalReduction>
    </actuator>
  </transmission>
  <transmission name="left_rear_ankle_trans">
    <type>transmission_interface/SimpleTransmission</type>
    <joint name="left_rear_lower_leg_joint">
      <hardwareInterface>hardware_interface/PositionJointInterface</hardwareInterface>
    </joint>
    <actuator name="left_rear_ankle_motor">
      <hardwareInterface>hardware_interface/PositionJointInterface</hardwareInterface>
      <mechanicalReduction>1</mechanicalReduction>
    </actuator>
  </transmission>
  <transmission name="right_rear_hip_trans">
    <type>transmission_interface/SimpleTransmission</type>
    <joint name="right_rear_hip_joint">
      <hardwareInterface>hardware_interface/PositionJointInterface</hardwareInterface>
    </joint>
    <actuator name="right_rear_hip_motor">
      <hardwareInterface>hardware_interface/PositionJointInterface</hardwareInterface>
      <mechanicalReduction>1</mechanicalReduction>
    </actuator>
  </transmission>
  <transmission name="right_rear_knee_trans">
    <type>transmission_interface/SimpleTransmission</type>
    <joint name="right_rear_upper_leg_joint">
      <hardwareInterface>hardware_interface/PositionJointInterface</hardwareInterface>
    </joint>
    <actuator name="right_rear_knee_motor">
      <hardwareInterface>hardware_interface/PositionJointInterface</hardwareInterface>
      <mechanicalReduction>1</mechanicalReduction>
    </actuator>
  </transmission>
  <transmission name="right_rear_ankle_trans">
    <type>transmission_interface/SimpleTransmission</type>
    <joint name="right_rear_lower_leg_joint">
      <hardwareInterface>hardware_interface/PositionJointInterface</hardwareInterface>
    </joint>
    <actuator name="right_rear_ankle_motor">
      <hardwareInterface>hardware_interface/PositionJointInterface</hardwareInterface>
      <mechanicalReduction>1</mechanicalReduction>
    </actuator>
  </transmission>
  <!-- Hip Motor Link -->
  <link name="right_rear_hip_motor_link">
    <visual>
      <origin xyz="0 0 0.02"/>
      <geometry>
        <cylinder length="0.02" radius="0.015"/>
      </geometry>
      <material name="grey"/>
    </visual>
    <collision>
      <origin xyz="0 0 0.02"/>
      <geometry>
        <cylinder length="0.02" radius="0.015"/>
      </geometry>
    </collision>
    <inertial>
      <mass value="0.05"/>
      <inertia ixx="0.00001" ixy="0.0" ixz="0.0" iyy="0.00001" iyz="0.0" izz="0.00001"/>
    </inertial>
  </link>
  <!-- Fixed joint gắn hip motor vào chassis -->
  <joint name="right_rear_hip_motor_fixed" type="fixed">
    <parent link="chassis"/>
    <child link="right_rear_hip_motor_link"/>
    <origin xyz="-0.15 -0.1 0.075"/>
  </joint>
  <!-- Hip Joint -->
  <joint name="right_rear_hip_joint" type="revolute">
    <parent link="right_rear_hip_motor_link"/>
    <child link="right_rear_thigh"/>
    <origin xyz="0 0 0"/>
    <axis xyz="0 1 0"/>
    <limit effort="5" lower="-1.57" upper="1.57" velocity="2.0"/>
  </joint>
  <!-- Thigh Link -->
  <link name="right_rear_thigh">
    <visual>
      <origin xyz="0 0 -0.075"/>
      <geometry>
        <box size="0.05 0.05 0.15"/>
      </geometry>
      <material name="blue"/>
    </visual>
    <collision>
      <origin xyz="0 0 -0.075"/>
      <geometry>
        <box size="0.05 0.05 0.15"/>
      </geometry>
    </collision>
    <inertial>
      <mass value="0.2"/>
      <origin rpy="0 0 0" xyz="0 0 0"/>
      <inertia ixx="0.0004166666666666667" ixy="0.0" ixz="0.0" iyy="0.0004166666666666667" iyz="0.0" izz="8.333333333333334e-05"/>
    </inertial>
  </link>
  <!-- Knee Motor Link -->
  <link name="right_rear_knee_motor_link">
    <visual>
      <origin xyz="0 0 -0.01"/>
      <geometry>
        <cylinder length="0.02" radius="0.012"/>
      </geometry>
      <material name="grey"/>
    </visual>
    <collision>
      <origin xyz="0 0 -0.01"/>
      <geometry>
        <cylinder length="0.02" radius="0.012"/>
      </geometry>
    </collision>
    <inertial>
      <mass value="0.03"/>
      <inertia ixx="0.00001" ixy="0.0" ixz="0.0" iyy="0.00001" iyz="0.0" izz="0.00001"/>
    </inertial>
  </link>
  <!-- Fixed joint gắn knee motor vào thigh -->
  <joint name="right_rear_knee_motor_fixed" type="fixed">
    <parent link="right_rear_thigh"/>
    <child link="right_rear_knee_motor_link"/>
    <origin xyz="0 0 -0.15"/>
  </joint>
  <!-- Knee Joint -->
  <joint name="right_rear_upper_leg_joint" type="revolute">
    <parent link="right_rear_knee_motor_link"/>
    <child link="right_rear_shank"/>
    <origin xyz="0 0 0"/>
    <axis xyz="0 1 0"/>
    <limit effort="5" lower="-1.57" upper="1.57" velocity="2.0"/>
  </joint>
  <!-- Shank Link -->
  <link name="right_rear_shank">
    <visual>
      <origin xyz="0 0 -0.075"/>
      <geometry>
        <box size="0.04 0.04 0.15"/>
      </geometry>
      <material name="red"/>
    </visual>
    <collision>
      <origin xyz="0 0 -0.075"/>
      <geometry>
        <box size="0.04 0.04 0.15"/>
      </geometry>
    </collision>
    <inertial>
      <mass value="0.2"/>
      <origin rpy="0 0 0" xyz="0 0 0"/>
      <inertia ixx="0.00040166666666666665" ixy="0.0" ixz="0.0" iyy="0.00040166666666666665" iyz="0.0" izz="5.333333333333333e-05"/>
    </inertial>
  </link>
  <!-- Ankle Motor Link -->
  <link name="right_rear_ankle_motor_link">
    <visual>
      <origin xyz="0 0 -0.01"/>
      <geometry>
        <cylinder length="0.02" radius="0.012"/>
      </geometry>
      <material name="grey"/>
    </visual>
    <collision>
      <origin xyz="0 0 -0.01"/>
      <geometry>
        <cylinder length="0.02" radius="0.012"/>
      </geometry>
    </collision>
    <inertial>
      <mass value="0.03"/>
      <inertia ixx="0.00001" ixy="0.0" ixz="0.0" iyy="0.00001" iyz="0.0" izz="0.00001"/>
    </inertial>
  </link>
  <!-- Fixed joint gắn ankle motor vào shank -->
  <joint name="right_rear_ankle_motor_fixed" type="fixed">
    <parent link="right_rear_shank"/>
    <child link="right_rear_ankle_motor_link"/>
    <origin xyz="0 0 -0.15"/>
  </joint>
  <!-- Ankle Joint -->
  <joint name="right_rear_lower_leg_joint" type="revolute">
    <parent link="right_rear_ankle_motor_link"/>
    <child link="right_rear_foot"/>
    <origin xyz="0 0 0"/>
    <axis xyz="0 1 0"/>
    <limit effort="5" lower="-1.57" upper="1.57" velocity="2.0"/>
  </joint>
  <!-- Foot Link -->
  <link name="right_rear_foot">
    <visual>
      <geometry>
        <sphere radius="0.03"/>
      </geometry>
      <material name="black"/>
    </visual>
    <collision>
      <geometry>
        <sphere radius="0.03"/>
      </geometry>
    </collision>
    <inertial>
      <origin rpy="0 0 0" xyz="0 0 0"/>
      <mass value="0.1"/>
      <inertia ixx="3.600000000000001e-05" ixy="0.0" ixz="0.0" iyy="3.600000000000001e-05" iyz="0.0" izz="3.600000000000001e-05"/>
    </inertial>
  </link>
  <transmission name="left_front_hip_trans">
    <type>transmission_interface/SimpleTransmission</type>
    <joint name="left_front_hip_joint">
      <hardwareInterface>hardware_interface/PositionJointInterface</hardwareInterface>
    </joint>
    <actuator name="left_front_hip_motor">
      <hardwareInterface>hardware_interface/PositionJointInterface</hardwareInterface>
      <mechanicalReduction>1</mechanicalReduction>
    </actuator>
  </transmission>
  <transmission name="left_front_knee_trans">
    <type>transmission_interface/SimpleTransmission</type>
    <joint name="left_front_upper_leg_joint">
      <hardwareInterface>hardware_interface/PositionJointInterface</hardwareInterface>
    </joint>
    <actuator name="left_front_knee_motor">
      <hardwareInterface>hardware_interface/PositionJointInterface</hardwareInterface>
      <mechanicalReduction>1</mechanicalReduction>
    </actuator>
  </transmission>
  <transmission name="left_front_ankle_trans">
    <type>transmission_interface/SimpleTransmission</type>
    <joint name="left_front_lower_leg_joint">
      <hardwareInterface>hardware_interface/PositionJointInterface</hardwareInterface>
    </joint>
    <actuator name="left_front_ankle_motor">
      <hardwareInterface>hardware_interface/PositionJointInterface</hardwareInterface>
      <mechanicalReduction>1</mechanicalReduction>
    </actuator>
  </transmission>
  <transmission name="right_front_hip_trans">
    <type>transmission_interface/SimpleTransmission</type>
    <joint name="right_front_hip_joint">
      <hardwareInterface>hardware_interface/PositionJointInterface</hardwareInterface>
    </joint>
    <actuator name="right_front_hip_motor">
      <hardwareInterface>hardware_interface/PositionJointInterface</hardwareInterface>
      <mechanicalReduction>1</mechanicalReduction>
    </actuator>
  </transmission>
  <transmission name="right_front_knee_trans">
    <type>transmission_interface/SimpleTransmission</type>
    <joint name="right_front_upper_leg_joint">
      <hardwareInterface>hardware_interface/PositionJointInterface</hardwareInterface>
    </joint>
    <actuator name="right_front_knee_motor">
      <hardwareInterface>hardware_interface/PositionJointInterface</hardwareInterface>
      <mechanicalReduction>1</mechanicalReduction>
    </actuator>
  </transmission>
  <transmission name="right_front_ankle_trans">
    <type>transmission_interface/SimpleTransmission</type>
    <joint name="right_front_lower_leg_joint">
      <hardwareInterface>hardware_interface/PositionJointInterface</hardwareInterface>
    </joint>
    <actuator name="right_front_ankle_motor">
      <hardwareInterface>hardware_interface/PositionJointInterface</hardwareInterface>
      <mechanicalReduction>1</mechanicalReduction>
    </actuator>
  </transmission>
  <transmission name="left_rear_hip_trans">
    <type>transmission_interface/SimpleTransmission</type>
    <joint name="left_rear_hip_joint">
      <hardwareInterface>hardware_interface/PositionJointInterface</hardwareInterface>
    </joint>
    <actuator name="left_rear_hip_motor">
      <hardwareInterface>hardware_interface/PositionJointInterface</hardwareInterface>
      <mechanicalReduction>1</mechanicalReduction>
    </actuator>
  </transmission>
  <transmission name="left_rear_knee_trans">
    <type>transmission_interface/SimpleTransmission</type>
    <joint name="left_rear_upper_leg_joint">
      <hardwareInterface>hardware_interface/PositionJointInterface</hardwareInterface>
    </joint>
    <actuator name="left_rear_knee_motor">
      <hardwareInterface>hardware_interface/PositionJointInterface</hardwareInterface>
      <mechanicalReduction>1</mechanicalReduction>
    </actuator>
  </transmission>
  <transmission name="left_rear_ankle_trans">
    <type>transmission_interface/SimpleTransmission</type>
    <joint name="left_rear_lower_leg_joint">
      <hardwareInterface>hardware_interface/PositionJointInterface</hardwareInterface>
    </joint>
    <actuator name="left_rear_ankle_motor">
      <hardwareInterface>hardware_interface/PositionJointInterface</hardwareInterface>
      <mechanicalReduction>1</mechanicalReduction>
    </actuator>
  </transmission>
  <transmission name="right_rear_hip_trans">
    <type>transmission_interface/SimpleTransmission</type>
    <joint name="right_rear_hip_joint">
      <hardwareInterface>hardware_interface/PositionJointInterface</hardwareInterface>
    </joint>
    <actuator name="right_rear_hip_motor">
      <hardwareInterface>hardware_interface/PositionJointInterface</hardwareInterface>
      <mechanicalReduction>1</mechanicalReduction>
    </actuator>
  </transmission>
  <transmission name="right_rear_knee_trans">
    <type>transmission_interface/SimpleTransmission</type>
    <joint name="right_rear_upper_leg_joint">
      <hardwareInterface>hardware_interface/PositionJointInterface</hardwareInterface>
    </joint>
    <actuator name="right_rear_knee_motor">
      <hardwareInterface>hardware_interface/PositionJointInterface</hardwareInterface>
      <mechanicalReduction>1</mechanicalReduction>
    </actuator>
  </transmission>
  <transmission name="right_rear_ankle_trans">
    <type>transmission_interface/SimpleTransmission</type>
    <joint name="right_rear_lower_leg_joint">
      <hardwareInterface>hardware_interface/PositionJointInterface</hardwareInterface>
    </joint>
    <actuator name="right_rear_ankle_motor">
      <hardwareInterface>hardware_interface/PositionJointInterface</hardwareInterface>
      <mechanicalReduction>1</mechanicalReduction>
    </actuator>
  </transmission>
  <!-- HEAD LINK -->
  <joint name="head_joint" type="fixed">
    <parent link="base_link"/>
    <child link="head"/>
    <origin xyz="0 0 0.15"/>
  </joint>
  <link name="head">
    <visual>
      <origin xyz="0 0 0.05"/>
      <geometry>
        <box size="0.1 0.1 0.1"/>
      </geometry>
      <material name="orange"/>
    </visual>
    <collision>
      <origin xyz="0 0 0.05"/>
      <geometry>
        <box size="0.1 0.1 0.1"/>
      </geometry>
    </collision>
    <inertial>
      <origin rpy="0 0 0" xyz="0 0 0.05"/>
      <mass value="0.2"/>
      <inertia ixx="0.0003333333333333334" ixy="0.0" ixz="0.0" iyy="0.0003333333333333334" iyz="0.0" izz="0.0003333333333333334"/>
    </inertial>
  </link>
  <ros2_control name="FirstRobot" type="system">
    <hardware>
      <plugin>gz_ros2_control/GazeboSimSystem</plugin>
    </hardware>
    <joint name="left_front_hip_joint">
      <command_interface name="position"/>
      <state_interface name="position"/>
      <state_interface name="velocity"/>
    </joint>
    <joint name="left_front_upper_leg_joint">
      <command_interface name="position"/>
      <state_interface name="position"/>
      <state_interface name="velocity"/>
    </joint>
    <joint name="left_front_lower_leg_joint">
      <command_interface name="position"/>
      <state_interface name="position"/>
      <state_interface name="velocity"/>
    </joint>
    <joint name="right_front_hip_joint">
      <command_interface name="position"/>
      <state_interface name="position"/>
      <state_interface name="velocity"/>
    </joint>
    <joint name="right_front_upper_leg_joint">
      <command_interface name="position"/>
      <state_interface name="position"/>
      <state_interface name="velocity"/>
    </joint>
    <joint name="right_front_lower_leg_joint">
      <command_interface name="position"/>
      <state_interface name="position"/>
      <state_interface name="velocity"/>
    </joint>
    <joint name="left_rear_hip_joint">
      <command_interface name="position"/>
      <state_interface name="position"/>
      <state_interface name="velocity"/>
    </joint>
    <joint name="left_rear_upper_leg_joint">
      <command_interface name="position"/>
      <state_interface name="position"/>
      <state_interface name="velocity"/>
    </joint>
    <joint name="left_rear_lower_leg_joint">
      <command_interface name="position"/>
      <state_interface name="position"/>
      <state_interface name="velocity"/>
    </joint>
    <joint name="right_rear_hip_joint">
      <command_interface name="position"/>
      <state_interface name="position"/>
      <state_interface name="velocity"/>
    </joint>
    <joint name="right_rear_upper_leg_joint">
      <command_interface name="position"/>
      <state_interface name="position"/>
      <state_interface name="velocity"/>
    </joint>
    <joint name="right_rear_lower_leg_joint">
      <command_interface name="position"/>
      <state_interface name="position"/>
      <state_interface name="velocity"/>
    </joint>
  </ros2_control>
  <gazebo>
    <plugin filename="gz_ros2_control-system" name="gz_ros2_control::GazeboSimROS2ControlPlugin">
      <parameters>/home/phieu/ros2-learning/src/install/first_robot/share/first_robot/config/ros_control.yaml</parameters>
    </plugin>
  </gazebo>
  <!-- <xacro:include filename="lidar_2d_camera.xacro" />
    <xacro:include filename="camera.xacro" />
    <xacro:include filename="imu_link.xacro" /> -->
</robot>
