<?xml version="1.0" ?>
<!-- =================================================================================== -->
<!-- |    This document was autogenerated by xacro from first_robot/description/robot.urdf.xacro | -->
<!-- |    EDITING THIS FILE BY HAND IS NOT RECOMMENDED                                 | -->
<!-- =================================================================================== -->
<robot name="my_robot">
  <!-- Specify some standard inertial calculations https://en.wikipedia.org/wiki/List_of_moments_of_inertia -->
  <!-- These make use of xacro's mathematical functionality -->
  <material name="white">
    <color rgba="1 1 1 1"/>
  </material>
  <material name="orange">
    <color rgba="1 0.3 0.1 1"/>
  </material>
  <material name="blue">
    <color rgba="0.2 0.2 1 1"/>
  </material>
  <material name="black">
    <color rgba="0 0 0 1"/>
  </material>
  <material name="red">
    <color rgba="1 0 0 1"/>
  </material>
  <material name="grey">
    <color rgba="0.5 0.5 0.5 1"/>
  </material>
  <!-- BASE LINK -->
  <link name="base_link">
    <inertial>
      <mass value="0.5"/>
      <!-- Giảm từ 2.0 -->
      <origin xyz="0 0 0.1"/>
      <inertia ixx="0.1" ixy="0" ixz="0" iyy="0.1" iyz="0" izz="0.1"/>
    </inertial>
  </link>
  <!-- CHASSIS LINK -->
  <joint name="chassis_joint" type="fixed">
    <parent link="base_link"/>
    <child link="chassis"/>
    <origin xyz="0 0 0"/>
  </joint>
  <link name="chassis">
    <visual>
      <origin xyz="0 0 0.075"/>
      <geometry>
        <box size="0.5 0.2 0.15"/>
      </geometry>
      <material name="white"/>
    </visual>
    <collision>
      <origin xyz="0.15 0 0.075"/>
      <geometry>
        <box size="0.5 0.2 0.15"/>
      </geometry>
    </collision>
    <inertial>
      <origin rpy="0 0 0" xyz="0 0 0.075"/>
      <mass value="0.5"/>
      <inertia ixx="0.0026041666666666665" ixy="0.0" ixz="0.0" iyy="0.011354166666666667" iyz="0.0" izz="0.012083333333333335"/>
    </inertial>
  </link>
  <!-- FL (Front Left) LEG -->
  <!-- Hip Motor Link -->
  <link name="left_front_hip_motor_link">
    <visual>
      <origin xyz="0 0 0.02"/>
      <geometry>
        <cylinder length="0.02" radius="0.015"/>
      </geometry>
      <material name="grey"/>
    </visual>
    <collision>
      <origin xyz="0 0 0.02"/>
      <geometry>
        <cylinder length="0.02" radius="0.015"/>
      </geometry>
    </collision>
    <inertial>
      <mass value="0.05"/>
      <inertia ixx="0.00001" ixy="0.0" ixz="0.0" iyy="0.00001" iyz="0.0" izz="0.00001"/>
    </inertial>
  </link>
  <!-- Fixed joint gắn hip motor vào chassis -->
  <joint name="left_front_hip_motor_fixed" type="fixed">
    <parent link="chassis"/>
    <child link="left_front_hip_motor_link"/>
    <origin xyz="0.15 0.1 0.075"/>
  </joint>
  <!-- Hip Joint -->
  <joint name="left_front_hip_joint" type="revolute">
    <parent link="left_front_hip_motor_link"/>
    <child link="left_front_thigh"/>
    <origin xyz="0 0 0"/>
    <axis xyz="0 1 0"/>
    <limit effort="5" lower="-1.57" upper="1.57" velocity="2.0"/>
  </joint>
  <!-- Thigh Link -->
  <link name="left_front_thigh">
    <visual>
      <origin xyz="0 0 -0.075"/>
      <geometry>
        <box size="0.05 0.05 0.15"/>
      </geometry>
      <material name="blue"/>
    </visual>
    <collision>
      <origin xyz="0 0 -0.075"/>
      <geometry>
        <box size="0.05 0.05 0.15"/>
      </geometry>
    </collision>
    <inertial>
      <mass value="0.2"/>
      <origin rpy="0 0 0" xyz="0 0 0"/>
      <inertia ixx="0.0004166666666666667" ixy="0.0" ixz="0.0" iyy="0.0004166666666666667" iyz="0.0" izz="8.333333333333334e-05"/>
    </inertial>
  </link>
  <!-- Knee Motor Link -->
  <link name="left_front_knee_motor_link">
    <visual>
      <origin xyz="0 0 -0.01"/>
      <geometry>
        <cylinder length="0.02" radius="0.012"/>
      </geometry>
      <material name="grey"/>
    </visual>
    <collision>
      <origin xyz="0 0 -0.01"/>
      <geometry>
        <cylinder length="0.02" radius="0.012"/>
      </geometry>
    </collision>
    <inertial>
      <mass value="0.03"/>
      <inertia ixx="0.00001" ixy="0.0" ixz="0.0" iyy="0.00001" iyz="0.0" izz="0.00001"/>
    </inertial>
  </link>
  <!-- Fixed joint gắn knee motor vào thigh -->
  <joint name="left_front_knee_motor_fixed" type="fixed">
    <parent link="left_front_thigh"/>
    <child link="left_front_knee_motor_link"/>
    <origin xyz="0 0 -0.15"/>
  </joint>
  <!-- Knee Joint -->
  <joint name="left_front_upper_leg_joint" type="revolute">
    <parent link="left_front_knee_motor_link"/>
    <child link="left_front_shank"/>
    <origin xyz="0 0 0"/>
    <axis xyz="0 1 0"/>
    <limit effort="5" lower="-1.57" upper="1.57" velocity="2.0"/>
  </joint>
  <!-- Shank Link -->
  <link name="left_front_shank">
    <visual>
      <origin xyz="0 0 -0.075"/>
      <geometry>
        <box size="0.04 0.04 0.15"/>
      </geometry>
      <material name="red"/>
    </visual>
    <collision>
      <origin xyz="0 0 -0.075"/>
      <geometry>
        <box size="0.04 0.04 0.15"/>
      </geometry>
    </collision>
    <inertial>
      <mass value="0.2"/>
      <origin rpy="0 0 0" xyz="0 0 0"/>
      <inertia ixx="0.00040166666666666665" ixy="0.0" ixz="0.0" iyy="0.00040166666666666665" iyz="0.0" izz="5.333333333333333e-05"/>
    </inertial>
  </link>
  <!-- Ankle Motor Link -->
  <link name="left_front_ankle_motor_link">
    <visual>
      <origin xyz="0 0 -0.01"/>
      <geometry>
        <cylinder length="0.02" radius="0.012"/>
      </geometry>
      <material name="grey"/>
    </visual>
    <collision>
      <origin xyz="0 0 -0.01"/>
      <geometry>
        <cylinder length="0.02" radius="0.012"/>
      </geometry>
    </collision>
    <inertial>
      <mass value="0.03"/>
      <inertia ixx="0.00001" ixy="0.0" ixz="0.0" iyy="0.00001" iyz="0.0" izz="0.00001"/>
    </inertial>
  </link>
  <!-- Fixed joint gắn ankle motor vào shank -->
  <joint name="left_front_ankle_motor_fixed" type="fixed">
    <parent link="left_front_shank"/>
    <child link="left_front_ankle_motor_link"/>
    <origin xyz="0 0 -0.15"/>
  </joint>
  <!-- Ankle Joint -->
  <joint name="left_front_lower_leg_joint" type="revolute">
    <parent link="left_front_ankle_motor_link"/>
    <child link="left_front_foot"/>
    <origin xyz="0 0 0"/>
    <axis xyz="0 1 0"/>
    <limit effort="5" lower="-1.57" upper="1.57" velocity="2.0"/>
  </joint>
  <!-- Foot Link -->
  <link name="left_front_foot">
    <visual>
      <geometry>
        <sphere radius="0.03"/>
      </geometry>
      <material name="black"/>
    </visual>
    <collision>
      <geometry>
        <sphere radius="0.03"/>
      </geometry>
    </collision>
    <inertial>
      <origin rpy="0 0 0" xyz="0 0 0"/>
      <mass value="0.1"/>
      <inertia ixx="3.600000000000001e-05" ixy="0.0" ixz="0.0" iyy="3.600000000000001e-05" iyz="0.0" izz="3.600000000000001e-05"/>
    </inertial>
  </link>
  <transmission name="left_front_hip_trans">
    <type>transmission_interface/SimpleTransmission</type>
    <joint name="left_front_hip_joint">
      <hardwareInterface>hardware_interface/PositionJointInterface</hardwareInterface>
    </joint>
    <actuator name="left_front_hip_motor">
      <hardwareInterface>hardware_interface/PositionJointInterface</hardwareInterface>
      <mechanicalReduction>1</mechanicalReduction>
    </actuator>
  </transmission>
  <transmission name="left_front_knee_trans">
    <type>transmission_interface/SimpleTransmission</type>
    <joint name="left_front_upper_leg_joint">
      <hardwareInterface>hardware_interface/PositionJointInterface</hardwareInterface>
    </joint>
    <actuator name="left_front_knee_motor">
      <hardwareInterface>hardware_interface/PositionJointInterface</hardwareInterface>
      <mechanicalReduction>1</mechanicalReduction>
    </actuator>
  </transmission>
  <transmission name="left_front_ankle_trans">
    <type>transmission_interface/SimpleTransmission</type>
    <joint name="left_front_lower_leg_joint">
      <hardwareInterface>hardware_interface/PositionJointInterface</hardwareInterface>
    </joint>
    <actuator name="left_front_ankle_motor">
      <hardwareInterface>hardware_interface/PositionJointInterface</hardwareInterface>
      <mechanicalReduction>1</mechanicalReduction>
    </actuator>
  </transmission>
  <transmission name="right_front_hip_trans">
    <type>transmission_interface/SimpleTransmission</type>
    <joint name="right_front_hip_joint">
      <hardwareInterface>hardware_interface/PositionJointInterface</hardwareInterface>
    </joint>
    <actuator name="right_front_hip_motor">
      <hardwareInterface>hardware_interface/PositionJointInterface</hardwareInterface>
      <mechanicalReduction>1</mechanicalReduction>
    </actuator>
  </transmission>
  <transmission name="right_front_knee_trans">
    <type>transmission_interface/SimpleTransmission</type>
    <joint name="right_front_upper_leg_joint">
      <hardwareInterface>hardware_interface/PositionJointInterface</hardwareInterface>
    </joint>
    <actuator name="right_front_knee_motor">
      <hardwareInterface>hardware_interface/PositionJointInterface</hardwareInterface>
      <mechanicalReduction>1</mechanicalReduction>
    </actuator>
  </transmission>
  <transmission name="right_front_ankle_trans">
    <type>transmission_interface/SimpleTransmission</type>
    <joint name="right_front_lower_leg_joint">
      <hardwareInterface>hardware_interface/PositionJointInterface</hardwareInterface>
    </joint>
    <actuator name="right_front_ankle_motor">
      <hardwareInterface>hardware_interface/PositionJointInterface</hardwareInterface>
      <mechanicalReduction>1</mechanicalReduction>
    </actuator>
  </transmission>
  <transmission name="left_rear_hip_trans">
    <type>transmission_interface/SimpleTransmission</type>
    <joint name="left_rear_hip_joint">
      <hardwareInterface>hardware_interface/PositionJointInterface</hardwareInterface>
    </joint>
    <actuator name="left_rear_hip_motor">
      <hardwareInterface>hardware_interface/PositionJointInterface</hardwareInterface>
      <mechanicalReduction>1</mechanicalReduction>
    </actuator>
  </transmission>
  <transmission name="left_rear_knee_trans">
    <type>transmission_interface/SimpleTransmission</type>
    <joint name="left_rear_upper_leg_joint">
      <hardwareInterface>hardware_interface/PositionJointInterface</hardwareInterface>
    </joint>
    <actuator name="left_rear_knee_motor">
      <hardwareInterface>hardware_interface/PositionJointInterface</hardwareInterface>
      <mechanicalReduction>1</mechanicalReduction>
    </actuator>
  </transmission>
  <transmission name="left_rear_ankle_trans">
    <type>transmission_interface/SimpleTransmission</type>
    <joint name="left_rear_lower_leg_joint">
      <hardwareInterface>hardware_interface/PositionJointInterface</hardwareInterface>
    </joint>
    <actuator name="left_rear_ankle_motor">
      <hardwareInterface>hardware_interface/PositionJointInterface</hardwareInterface>
      <mechanicalReduction>1</mechanicalReduction>
    </actuator>
  </transmission>
  <transmission name="right_rear_hip_trans">
    <type>transmission_interface/SimpleTransmission</type>
    <joint name="right_rear_hip_joint">
      <hardwareInterface>hardware_interface/PositionJointInterface</hardwareInterface>
    </joint>
    <actuator name="right_rear_hip_motor">
      <hardwareInterface>hardware_interface/PositionJointInterface</hardwareInterface>
      <mechanicalReduction>1</mechanicalReduction>
    </actuator>
  </transmission>
  <transmission name="right_rear_knee_trans">
    <type>transmission_interface/SimpleTransmission</type>
    <joint name="right_rear_upper_leg_joint">
      <hardwareInterface>hardware_interface/PositionJointInterface</hardwareInterface>
    </joint>
    <actuator name="right_rear_knee_motor">
      <hardwareInterface>hardware_interface/PositionJointInterface</hardwareInterface>
      <mechanicalReduction>1</mechanicalReduction>
    </actuator>
  </transmission>
  <transmission name="right_rear_ankle_trans">
    <type>transmission_interface/SimpleTransmission</type>
    <joint name="right_rear_lower_leg_joint">
      <hardwareInterface>hardware_interface/PositionJointInterface</hardwareInterface>
    </joint>
    <actuator name="right_rear_ankle_motor">
      <hardwareInterface>hardware_interface/PositionJointInterface</hardwareInterface>
      <mechanicalReduction>1</mechanicalReduction>
    </actuator>
  </transmission>
  <!-- Hip Motor Link -->
  <link name="right_front_hip_motor_link">
    <visual>
      <origin xyz="0 0 0.02"/>
      <geometry>
        <cylinder length="0.02" radius="0.015"/>
      </geometry>
      <material name="grey"/>
    </visual>
    <collision>
      <origin xyz="0 0 0.02"/>
      <geometry>
        <cylinder length="0.02" radius="0.015"/>
      </geometry>
    </collision>
    <inertial>
      <mass value="0.05"/>
      <inertia ixx="0.00001" ixy="0.0" ixz="0.0" iyy="0.00001" iyz="0.0" izz="0.00001"/>
    </inertial>
  </link>
  <!-- Fixed joint gắn hip motor vào chassis -->
  <joint name="right_front_hip_motor_fixed" type="fixed">
    <parent link="chassis"/>
    <child link="right_front_hip_motor_link"/>
    <origin xyz="0.15 -0.1 0.075"/>
  </joint>
  <!-- Hip Joint -->
  <joint name="right_front_hip_joint" type="revolute">
    <parent link="right_front_hip_motor_link"/>
    <child link="right_front_thigh"/>
    <origin xyz="0 0 0"/>
    <axis xyz="0 1 0"/>
    <limit effort="5" lower="-1.57" upper="1.57" velocity="2.0"/>
  </joint>
  <!-- Thigh Link -->
  <link name="right_front_thigh">
    <visual>
      <origin xyz="0 0 -0.075"/>
      <geometry>
        <box size="0.05 0.05 0.15"/>
      </geometry>
      <material name="blue"/>
    </visual>
    <collision>
      <origin xyz="0 0 -0.075"/>
      <geometry>
        <box size="0.05 0.05 0.15"/>
      </geometry>
    </collision>
    <inertial>
      <mass value="0.2"/>
      <origin rpy="0 0 0" xyz="0 0 0"/>
      <inertia ixx="0.0004166666666666667" ixy="0.0" ixz="0.0" iyy="0.0004166666666666667" iyz="0.0" izz="8.333333333333334e-05"/>
    </inertial>
  </link>
  <!-- Knee Motor Link -->
  <link name="right_front_knee_motor_link">
    <visual>
      <origin xyz="0 0 -0.01"/>
      <geometry>
        <cylinder length="0.02" radius="0.012"/>
      </geometry>
      <material name="grey"/>
    </visual>
    <collision>
      <origin xyz="0 0 -0.01"/>
      <geometry>
        <cylinder length="0.02" radius="0.012"/>
      </geometry>
    </collision>
    <inertial>
      <mass value="0.03"/>
      <inertia ixx="0.00001" ixy="0.0" ixz="0.0" iyy="0.00001" iyz="0.0" izz="0.00001"/>
    </inertial>
  </link>
  <!-- Fixed joint gắn knee motor vào thigh -->
  <joint name="right_front_knee_motor_fixed" type="fixed">
    <parent link="right_front_thigh"/>
    <child link="right_front_knee_motor_link"/>
    <origin xyz="0 0 -0.15"/>
  </joint>
  <!-- Knee Joint -->
  <joint name="right_front_upper_leg_joint" type="revolute">
    <parent link="right_front_knee_motor_link"/>
    <child link="right_front_shank"/>
    <origin xyz="0 0 0"/>
    <axis xyz="0 1 0"/>
    <limit effort="5" lower="-1.57" upper="1.57" velocity="2.0"/>
  </joint>
  <!-- Shank Link -->
  <link name="right_front_shank">
    <visual>
      <origin xyz="0 0 -0.075"/>
      <geometry>
        <box size="0.04 0.04 0.15"/>
      </geometry>
      <material name="red"/>
    </visual>
    <collision>
      <origin xyz="0 0 -0.075"/>
      <geometry>
        <box size="0.04 0.04 0.15"/>
      </geometry>
    </collision>
    <inertial>
      <mass value="0.2"/>
      <origin rpy="0 0 0" xyz="0 0 0"/>
      <inertia ixx="0.00040166666666666665" ixy="0.0" ixz="0.0" iyy="0.00040166666666666665" iyz="0.0" izz="5.333333333333333e-05"/>
    </inertial>
  </link>
  <!-- Ankle Motor Link -->
  <link name="right_front_ankle_motor_link">
    <visual>
      <origin xyz="0 0 -0.01"/>
      <geometry>
        <cylinder length="0.02" radius="0.012"/>
      </geometry>
      <material name="grey"/>
    </visual>
    <collision>
      <origin xyz="0 0 -0.01"/>
      <geometry>
        <cylinder length="0.02" radius="0.012"/>
      </geometry>
    </collision>
    <inertial>
      <mass value="0.03"/>
      <inertia ixx="0.00001" ixy="0.0" ixz="0.0" iyy="0.00001" iyz="0.0" izz="0.00001"/>
    </inertial>
  </link>
  <!-- Fixed joint gắn ankle motor vào shank -->
  <joint name="right_front_ankle_motor_fixed" type="fixed">
    <parent link="right_front_shank"/>
    <child link="right_front_ankle_motor_link"/>
    <origin xyz="0 0 -0.15"/>
  </joint>
  <!-- Ankle Joint -->
  <joint name="right_front_lower_leg_joint" type="revolute">
    <parent link="right_front_ankle_motor_link"/>
    <child link="right_front_foot"/>
    <origin xyz="0 0 0"/>
    <axis xyz="0 1 0"/>
    <limit effort="5" lower="-1.57" upper="1.57" velocity="2.0"/>
  </joint>
  <!-- Foot Link -->
  <link name="right_front_foot">
    <visual>
      <geometry>
        <sphere radius="0.03"/>
      </geometry>
      <material name="black"/>
    </visual>
    <collision>
      <geometry>
        <sphere radius="0.03"/>
      </geometry>
    </collision>
    <inertial>
      <origin rpy="0 0 0" xyz="0 0 0"/>
      <mass value="0.1"/>
      <inertia ixx="3.600000000000001e-05" ixy="0.0" ixz="0.0" iyy="3.600000000000001e-05" iyz="0.0" izz="3.600000000000001e-05"/>
    </inertial>
  </link>
  <transmission name="left_front_hip_trans">
    <type>transmission_interface/SimpleTransmission</type>
    <joint name="left_front_hip_joint">
      <hardwareInterface>hardware_interface/PositionJointInterface</hardwareInterface>
    </joint>
    <actuator name="left_front_hip_motor">
      <hardwareInterface>hardware_interface/PositionJointInterface</hardwareInterface>
      <mechanicalReduction>1</mechanicalReduction>
    </actuator>
  </transmission>
  <transmission name="left_front_knee_trans">
    <type>transmission_interface/SimpleTransmission</type>
    <joint name="left_front_upper_leg_joint">
      <hardwareInterface>hardware_interface/PositionJointInterface</hardwareInterface>
    </joint>
    <actuator name="left_front_knee_motor">
      <hardwareInterface>hardware_interface/PositionJointInterface</hardwareInterface>
      <mechanicalReduction>1</mechanicalReduction>
    </actuator>
  </transmission>
  <transmission name="left_front_ankle_trans">
    <type>transmission_interface/SimpleTransmission</type>
    <joint name="left_front_lower_leg_joint">
      <hardwareInterface>hardware_interface/PositionJointInterface</hardwareInterface>
    </joint>
    <actuator name="left_front_ankle_motor">
      <hardwareInterface>hardware_interface/PositionJointInterface</hardwareInterface>
      <mechanicalReduction>1</mechanicalReduction>
    </actuator>
  </transmission>
  <transmission name="right_front_hip_trans">
    <type>transmission_interface/SimpleTransmission</type>
    <joint name="right_front_hip_joint">
      <hardwareInterface>hardware_interface/PositionJointInterface</hardwareInterface>
    </joint>
    <actuator name="right_front_hip_motor">
      <hardwareInterface>hardware_interface/PositionJointInterface</hardwareInterface>
      <mechanicalReduction>1</mechanicalReduction>
    </actuator>
  </transmission>
  <transmission name="right_front_knee_trans">
    <type>transmission_interface/SimpleTransmission</type>
    <joint name="right_front_upper_leg_joint">
      <hardwareInterface>hardware_interface/PositionJointInterface</hardwareInterface>
    </joint>
    <actuator name="right_front_knee_motor">
      <hardwareInterface>hardware_interface/PositionJointInterface</hardwareInterface>
      <mechanicalReduction>1</mechanicalReduction>
    </actuator>
  </transmission>
  <transmission name="right_front_ankle_trans">
    <type>transmission_interface/SimpleTransmission</type>
    <joint name="right_front_lower_leg_joint">
      <hardwareInterface>hardware_interface/PositionJointInterface</hardwareInterface>
    </joint>
    <actuator name="right_front_ankle_motor">
      <hardwareInterface>hardware_interface/PositionJointInterface</hardwareInterface>
      <mechanicalReduction>1</mechanicalReduction>
    </actuator>
  </transmission>
  <transmission name="left_rear_hip_trans">
    <type>transmission_interface/SimpleTransmission</type>
    <joint name="left_rear_hip_joint">
      <hardwareInterface>hardware_interface/PositionJointInterface</hardwareInterface>
    </joint>
    <actuator name="left_rear_hip_motor">
      <hardwareInterface>hardware_interface/PositionJointInterface</hardwareInterface>
      <mechanicalReduction>1</mechanicalReduction>
    </actuator>
  </transmission>
  <transmission name="left_rear_knee_trans">
    <type>transmission_interface/SimpleTransmission</type>
    <joint name="left_rear_upper_leg_joint">
      <hardwareInterface>hardware_interface/PositionJointInterface</hardwareInterface>
    </joint>
    <actuator name="left_rear_knee_motor">
      <hardwareInterface>hardware_interface/PositionJointInterface</hardwareInterface>
      <mechanicalReduction>1</mechanicalReduction>
    </actuator>
  </transmission>
  <transmission name="left_rear_ankle_trans">
    <type>transmission_interface/SimpleTransmission</type>
    <joint name="left_rear_lower_leg_joint">
      <hardwareInterface>hardware_interface/PositionJointInterface</hardwareInterface>
    </joint>
    <actuator name="left_rear_ankle_motor">
      <hardwareInterface>hardware_interface/PositionJointInterface</hardwareInterface>
      <mechanicalReduction>1</mechanicalReduction>
    </actuator>
  </transmission>
  <transmission name="right_rear_hip_trans">
    <type>transmission_interface/SimpleTransmission</type>
    <joint name="right_rear_hip_joint">
      <hardwareInterface>hardware_interface/PositionJointInterface</hardwareInterface>
    </joint>
    <actuator name="right_rear_hip_motor">
      <hardwareInterface>hardware_interface/PositionJointInterface</hardwareInterface>
      <mechanicalReduction>1</mechanicalReduction>
    </actuator>
  </transmission>
  <transmission name="right_rear_knee_trans">
    <type>transmission_interface/SimpleTransmission</type>
    <joint name="right_rear_upper_leg_joint">
      <hardwareInterface>hardware_interface/PositionJointInterface</hardwareInterface>
    </joint>
    <actuator name="right_rear_knee_motor">
      <hardwareInterface>hardware_interface/PositionJointInterface</hardwareInterface>
      <mechanicalReduction>1</mechanicalReduction>
    </actuator>
  </transmission>
  <transmission name="right_rear_ankle_trans">
    <type>transmission_interface/SimpleTransmission</type>
    <joint name="right_rear_lower_leg_joint">
      <hardwareInterface>hardware_interface/PositionJointInterface</hardwareInterface>
    </joint>
    <actuator name="right_rear_ankle_motor">
      <hardwareInterface>hardware_interface/PositionJointInterface</hardwareInterface>
      <mechanicalReduction>1</mechanicalReduction>
    </actuator>
  </transmission>
  <!-- Hip Motor Link -->
  <link name="left_rear_hip_motor_link">
    <visual>
      <origin xyz="0 0 0.02"/>
      <geometry>
        <cylinder length="0.02" radius="0.015"/>
      </geometry>
      <material name="grey"/>
    </visual>
    <collision>
      <origin xyz="0 0 0.02"/>
      <geometry>
        <cylinder length="0.02" radius="0.015"/>
      </geometry>
    </collision>
    <inertial>
      <mass value="0.05"/>
      <inertia ixx="0.00001" ixy="0.0" ixz="0.0" iyy="0.00001" iyz="0.0" izz="0.00001"/>
    </inertial>
  </link>
  <!-- Fixed joint gắn hip motor vào chassis -->
  <joint name="left_rear_hip_motor_fixed" type="fixed">
    <parent link="chassis"/>
    <child link="left_rear_hip_motor_link"/>
    <origin xyz="-0.15 0.1 0.075"/>
  </joint>
  <!-- Hip Joint -->
  <joint name="left_rear_hip_joint" type="revolute">
    <parent link="left_rear_hip_motor_link"/>
    <child link="left_rear_thigh"/>
    <origin xyz="0 0 0"/>
    <axis xyz="0 1 0"/>
    <limit effort="5" lower="-1.57" upper="1.57" velocity="2.0"/>
  </joint>
  <!-- Thigh Link -->
  <link name="left_rear_thigh">
    <visual>
      <origin xyz="0 0 -0.075"/>
      <geometry>
        <box size="0.05 0.05 0.15"/>
      </geometry>
      <material name="blue"/>
    </visual>
    <collision>
      <origin xyz="0 0 -0.075"/>
      <geometry>
        <box size="0.05 0.05 0.15"/>
      </geometry>
    </collision>
    <inertial>
      <mass value="0.2"/>
      <origin rpy="0 0 0" xyz="0 0 0"/>
      <inertia ixx="0.0004166666666666667" ixy="0.0" ixz="0.0" iyy="0.0004166666666666667" iyz="0.0" izz="8.333333333333334e-05"/>
    </inertial>
  </link>
  <!-- Knee Motor Link -->
  <link name="left_rear_knee_motor_link">
    <visual>
      <origin xyz="0 0 -0.01"/>
      <geometry>
        <cylinder length="0.02" radius="0.012"/>
      </geometry>
      <material name="grey"/>
    </visual>
    <collision>
      <origin xyz="0 0 -0.01"/>
      <geometry>
        <cylinder length="0.02" radius="0.012"/>
      </geometry>
    </collision>
    <inertial>
      <mass value="0.03"/>
      <inertia ixx="0.00001" ixy="0.0" ixz="0.0" iyy="0.00001" iyz="0.0" izz="0.00001"/>
    </inertial>
  </link>
  <!-- Fixed joint gắn knee motor vào thigh -->
  <joint name="left_rear_knee_motor_fixed" type="fixed">
    <parent link="left_rear_thigh"/>
    <child link="left_rear_knee_motor_link"/>
    <origin xyz="0 0 -0.15"/>
  </joint>
  <!-- Knee Joint -->
  <joint name="left_rear_upper_leg_joint" type="revolute">
    <parent link="left_rear_knee_motor_link"/>
    <child link="left_rear_shank"/>
    <origin xyz="0 0 0"/>
    <axis xyz="0 1 0"/>
    <limit effort="5" lower="-1.57" upper="1.57" velocity="2.0"/>
  </joint>
  <!-- Shank Link -->
  <link name="left_rear_shank">
    <visual>
      <origin xyz="0 0 -0.075"/>
      <geometry>
        <box size="0.04 0.04 0.15"/>
      </geometry>
      <material name="red"/>
    </visual>
    <collision>
      <origin xyz="0 0 -0.075"/>
      <geometry>
        <box size="0.04 0.04 0.15"/>
      </geometry>
    </collision>
    <inertial>
      <mass value="0.2"/>
      <origin rpy="0 0 0" xyz="0 0 0"/>
      <inertia ixx="0.00040166666666666665" ixy="0.0" ixz="0.0" iyy="0.00040166666666666665" iyz="0.0" izz="5.333333333333333e-05"/>
    </inertial>
  </link>
  <!-- Ankle Motor Link -->
  <link name="left_rear_ankle_motor_link">
    <visual>
      <origin xyz="0 0 -0.01"/>
      <geometry>
        <cylinder length="0.02" radius="0.012"/>
      </geometry>
      <material name="grey"/>
    </visual>
    <collision>
      <origin xyz="0 0 -0.01"/>
      <geometry>
        <cylinder length="0.02" radius="0.012"/>
      </geometry>
    </collision>
    <inertial>
      <mass value="0.03"/>
      <inertia ixx="0.00001" ixy="0.0" ixz="0.0" iyy="0.00001" iyz="0.0" izz="0.00001"/>
    </inertial>
  </link>
  <!-- Fixed joint gắn ankle motor vào shank -->
  <joint name="left_rear_ankle_motor_fixed" type="fixed">
    <parent link="left_rear_shank"/>
    <child link="left_rear_ankle_motor_link"/>
    <origin xyz="0 0 -0.15"/>
  </joint>
  <!-- Ankle Joint -->
  <joint name="left_rear_lower_leg_joint" type="revolute">
    <parent link="left_rear_ankle_motor_link"/>
    <child link="left_rear_foot"/>
    <origin xyz="0 0 0"/>
    <axis xyz="0 1 0"/>
    <limit effort="5" lower="-1.57" upper="1.57" velocity="2.0"/>
  </joint>
  <!-- Foot Link -->
  <link name="left_rear_foot">
    <visual>
      <geometry>
        <sphere radius="0.03"/>
      </geometry>
      <material name="black"/>
    </visual>
    <collision>
      <geometry>
        <sphere radius="0.03"/>
      </geometry>
    </collision>
    <inertial>
      <origin rpy="0 0 0" xyz="0 0 0"/>
      <mass value="0.1"/>
      <inertia ixx="3.600000000000001e-05" ixy="0.0" ixz="0.0" iyy="3.600000000000001e-05" iyz="0.0" izz="3.600000000000001e-05"/>
    </inertial>
  </link>
  <transmission name="left_front_hip_trans">
    <type>transmission_interface/SimpleTransmission</type>
    <joint name="left_front_hip_joint">
      <hardwareInterface>hardware_interface/PositionJointInterface</hardwareInterface>
    </joint>
    <actuator name="left_front_hip_motor">
      <hardwareInterface>hardware_interface/PositionJointInterface</hardwareInterface>
      <mechanicalReduction>1</mechanicalReduction>
    </actuator>
  </transmission>
  <transmission name="left_front_knee_trans">
    <type>transmission_interface/SimpleTransmission</type>
    <joint name="left_front_upper_leg_joint">
      <hardwareInterface>hardware_interface/PositionJointInterface</hardwareInterface>
    </joint>
    <actuator name="left_front_knee_motor">
      <hardwareInterface>hardware_interface/PositionJointInterface</hardwareInterface>
      <mechanicalReduction>1</mechanicalReduction>
    </actuator>
  </transmission>
  <transmission name="left_front_ankle_trans">
    <type>transmission_interface/SimpleTransmission</type>
    <joint name="left_front_lower_leg_joint">
      <hardwareInterface>hardware_interface/PositionJointInterface</hardwareInterface>
    </joint>
    <actuator name="left_front_ankle_motor">
      <hardwareInterface>hardware_interface/PositionJointInterface</hardwareInterface>
      <mechanicalReduction>1</mechanicalReduction>
    </actuator>
  </transmission>
  <transmission name="right_front_hip_trans">
    <type>transmission_interface/SimpleTransmission</type>
    <joint name="right_front_hip_joint">
      <hardwareInterface>hardware_interface/PositionJointInterface</hardwareInterface>
    </joint>
    <actuator name="right_front_hip_motor">
      <hardwareInterface>hardware_interface/PositionJointInterface</hardwareInterface>
      <mechanicalReduction>1</mechanicalReduction>
    </actuator>
  </transmission>
  <transmission name="right_front_knee_trans">
    <type>transmission_interface/SimpleTransmission</type>
    <joint name="right_front_upper_leg_joint">
      <hardwareInterface>hardware_interface/PositionJointInterface</hardwareInterface>
    </joint>
    <actuator name="right_front_knee_motor">
      <hardwareInterface>hardware_interface/PositionJointInterface</hardwareInterface>
      <mechanicalReduction>1</mechanicalReduction>
    </actuator>
  </transmission>
  <transmission name="right_front_ankle_trans">
    <type>transmission_interface/SimpleTransmission</type>
    <joint name="right_front_lower_leg_joint">
      <hardwareInterface>hardware_interface/PositionJointInterface</hardwareInterface>
    </joint>
    <actuator name="right_front_ankle_motor">
      <hardwareInterface>hardware_interface/PositionJointInterface</hardwareInterface>
      <mechanicalReduction>1</mechanicalReduction>
    </actuator>
  </transmission>
  <transmission name="left_rear_hip_trans">
    <type>transmission_interface/SimpleTransmission</type>
    <joint name="left_rear_hip_joint">
      <hardwareInterface>hardware_interface/PositionJointInterface</hardwareInterface>
    </joint>
    <actuator name="left_rear_hip_motor">
      <hardwareInterface>hardware_interface/PositionJointInterface</hardwareInterface>
      <mechanicalReduction>1</mechanicalReduction>
    </actuator>
  </transmission>
  <transmission name="left_rear_knee_trans">
    <type>transmission_interface/SimpleTransmission</type>
    <joint name="left_rear_upper_leg_joint">
      <hardwareInterface>hardware_interface/PositionJointInterface</hardwareInterface>
    </joint>
    <actuator name="left_rear_knee_motor">
      <hardwareInterface>hardware_interface/PositionJointInterface</hardwareInterface>
      <mechanicalReduction>1</mechanicalReduction>
    </actuator>
  </transmission>
  <transmission name="left_rear_ankle_trans">
    <type>transmission_interface/SimpleTransmission</type>
    <joint name="left_rear_lower_leg_joint">
      <hardwareInterface>hardware_interface/PositionJointInterface</hardwareInterface>
    </joint>
    <actuator name="left_rear_ankle_motor">
      <hardwareInterface>hardware_interface/PositionJointInterface</hardwareInterface>
      <mechanicalReduction>1</mechanicalReduction>
    </actuator>
  </transmission>
  <transmission name="right_rear_hip_trans">
    <type>transmission_interface/SimpleTransmission</type>
    <joint name="right_rear_hip_joint">
      <hardwareInterface>hardware_interface/PositionJointInterface</hardwareInterface>
    </joint>
    <actuator name="right_rear_hip_motor">
      <hardwareInterface>hardware_interface/PositionJointInterface</hardwareInterface>
      <mechanicalReduction>1</mechanicalReduction>
    </actuator>
  </transmission>
  <transmission name="right_rear_knee_trans">
    <type>transmission_interface/SimpleTransmission</type>
    <joint name="right_rear_upper_leg_joint">
      <hardwareInterface>hardware_interface/PositionJointInterface</hardwareInterface>
    </joint>
    <actuator name="right_rear_knee_motor">
      <hardwareInterface>hardware_interface/PositionJointInterface</hardwareInterface>
      <mechanicalReduction>1</mechanicalReduction>
    </actuator>
  </transmission>
  <transmission name="right_rear_ankle_trans">
    <type>transmission_interface/SimpleTransmission</type>
    <joint name="right_rear_lower_leg_joint">
      <hardwareInterface>hardware_interface/PositionJointInterface</hardwareInterface>
    </joint>
    <actuator name="right_rear_ankle_motor">
      <hardwareInterface>hardware_interface/PositionJointInterface</hardwareInterface>
      <mechanicalReduction>1</mechanicalReduction>
    </actuator>
  </transmission>
  <!-- Hip Motor Link -->
  <link name="right_rear_hip_motor_link">
    <visual>
      <origin xyz="0 0 0.02"/>
      <geometry>
        <cylinder length="0.02" radius="0.015"/>
      </geometry>
      <material name="grey"/>
    </visual>
    <collision>
      <origin xyz="0 0 0.02"/>
      <geometry>
        <cylinder length="0.02" radius="0.015"/>
      </geometry>
    </collision>
    <inertial>
      <mass value="0.05"/>
      <inertia ixx="0.00001" ixy="0.0" ixz="0.0" iyy="0.00001" iyz="0.0" izz="0.00001"/>
    </inertial>
  </link>
  <!-- Fixed joint gắn hip motor vào chassis -->
  <joint name="right_rear_hip_motor_fixed" type="fixed">
    <parent link="chassis"/>
    <child link="right_rear_hip_motor_link"/>
    <origin xyz="-0.15 -0.1 0.075"/>
  </joint>
  <!-- Hip Joint -->
  <joint name="right_rear_hip_joint" type="revolute">
    <parent link="right_rear_hip_motor_link"/>
    <child link="right_rear_thigh"/>
    <origin xyz="0 0 0"/>
    <axis xyz="0 1 0"/>
    <limit effort="5" lower="-1.57" upper="1.57" velocity="2.0"/>
  </joint>
  <!-- Thigh Link -->
  <link name="right_rear_thigh">
    <visual>
      <origin xyz="0 0 -0.075"/>
      <geometry>
        <box size="0.05 0.05 0.15"/>
      </geometry>
      <material name="blue"/>
    </visual>
    <collision>
      <origin xyz="0 0 -0.075"/>
      <geometry>
        <box size="0.05 0.05 0.15"/>
      </geometry>
    </collision>
    <inertial>
      <mass value="0.2"/>
      <origin rpy="0 0 0" xyz="0 0 0"/>
      <inertia ixx="0.0004166666666666667" ixy="0.0" ixz="0.0" iyy="0.0004166666666666667" iyz="0.0" izz="8.333333333333334e-05"/>
    </inertial>
  </link>
  <!-- Knee Motor Link -->
  <link name="right_rear_knee_motor_link">
    <visual>
      <origin xyz="0 0 -0.01"/>
      <geometry>
        <cylinder length="0.02" radius="0.012"/>
      </geometry>
      <material name="grey"/>
    </visual>
    <collision>
      <origin xyz="0 0 -0.01"/>
      <geometry>
        <cylinder length="0.02" radius="0.012"/>
      </geometry>
    </collision>
    <inertial>
      <mass value="0.03"/>
      <inertia ixx="0.00001" ixy="0.0" ixz="0.0" iyy="0.00001" iyz="0.0" izz="0.00001"/>
    </inertial>
  </link>
  <!-- Fixed joint gắn knee motor vào thigh -->
  <joint name="right_rear_knee_motor_fixed" type="fixed">
    <parent link="right_rear_thigh"/>
    <child link="right_rear_knee_motor_link"/>
    <origin xyz="0 0 -0.15"/>
  </joint>
  <!-- Knee Joint -->
  <joint name="right_rear_upper_leg_joint" type="revolute">
    <parent link="right_rear_knee_motor_link"/>
    <child link="right_rear_shank"/>
    <origin xyz="0 0 0"/>
    <axis xyz="0 1 0"/>
    <limit effort="5" lower="-1.57" upper="1.57" velocity="2.0"/>
  </joint>
  <!-- Shank Link -->
  <link name="right_rear_shank">
    <visual>
      <origin xyz="0 0 -0.075"/>
      <geometry>
        <box size="0.04 0.04 0.15"/>
      </geometry>
      <material name="red"/>
    </visual>
    <collision>
      <origin xyz="0 0 -0.075"/>
      <geometry>
        <box size="0.04 0.04 0.15"/>
      </geometry>
    </collision>
    <inertial>
      <mass value="0.2"/>
      <origin rpy="0 0 0" xyz="0 0 0"/>
      <inertia ixx="0.00040166666666666665" ixy="0.0" ixz="0.0" iyy="0.00040166666666666665" iyz="0.0" izz="5.333333333333333e-05"/>
    </inertial>
  </link>
  <!-- Ankle Motor Link -->
  <link name="right_rear_ankle_motor_link">
    <visual>
      <origin xyz="0 0 -0.01"/>
      <geometry>
        <cylinder length="0.02" radius="0.012"/>
      </geometry>
      <material name="grey"/>
    </visual>
    <collision>
      <origin xyz="0 0 -0.01"/>
      <geometry>
        <cylinder length="0.02" radius="0.012"/>
      </geometry>
    </collision>
    <inertial>
      <mass value="0.03"/>
      <inertia ixx="0.00001" ixy="0.0" ixz="0.0" iyy="0.00001" iyz="0.0" izz="0.00001"/>
    </inertial>
  </link>
  <!-- Fixed joint gắn ankle motor vào shank -->
  <joint name="right_rear_ankle_motor_fixed" type="fixed">
    <parent link="right_rear_shank"/>
    <child link="right_rear_ankle_motor_link"/>
    <origin xyz="0 0 -0.15"/>
  </joint>
  <!-- Ankle Joint -->
  <joint name="right_rear_lower_leg_joint" type="revolute">
    <parent link="right_rear_ankle_motor_link"/>
    <child link="right_rear_foot"/>
    <origin xyz="0 0 0"/>
    <axis xyz="0 1 0"/>
    <limit effort="5" lower="-1.57" upper="1.57" velocity="2.0"/>
  </joint>
  <!-- Foot Link -->
  <link name="right_rear_foot">
    <visual>
      <geometry>
        <sphere radius="0.03"/>
      </geometry>
      <material name="black"/>
    </visual>
    <collision>
      <geometry>
        <sphere radius="0.03"/>
      </geometry>
    </collision>
    <inertial>
      <origin rpy="0 0 0" xyz="0 0 0"/>
      <mass value="0.1"/>
      <inertia ixx="3.600000000000001e-05" ixy="0.0" ixz="0.0" iyy="3.600000000000001e-05" iyz="0.0" izz="3.600000000000001e-05"/>
    </inertial>
  </link>
  <transmission name="left_front_hip_trans">
    <type>transmission_interface/SimpleTransmission</type>
    <joint name="left_front_hip_joint">
      <hardwareInterface>hardware_interface/PositionJointInterface</hardwareInterface>
    </joint>
    <actuator name="left_front_hip_motor">
      <hardwareInterface>hardware_interface/PositionJointInterface</hardwareInterface>
      <mechanicalReduction>1</mechanicalReduction>
    </actuator>
  </transmission>
  <transmission name="left_front_knee_trans">
    <type>transmission_interface/SimpleTransmission</type>
    <joint name="left_front_upper_leg_joint">
      <hardwareInterface>hardware_interface/PositionJointInterface</hardwareInterface>
    </joint>
    <actuator name="left_front_knee_motor">
      <hardwareInterface>hardware_interface/PositionJointInterface</hardwareInterface>
      <mechanicalReduction>1</mechanicalReduction>
    </actuator>
  </transmission>
  <transmission name="left_front_ankle_trans">
    <type>transmission_interface/SimpleTransmission</type>
    <joint name="left_front_lower_leg_joint">
      <hardwareInterface>hardware_interface/PositionJointInterface</hardwareInterface>
    </joint>
    <actuator name="left_front_ankle_motor">
      <hardwareInterface>hardware_interface/PositionJointInterface</hardwareInterface>
      <mechanicalReduction>1</mechanicalReduction>
    </actuator>
  </transmission>
  <transmission name="right_front_hip_trans">
    <type>transmission_interface/SimpleTransmission</type>
    <joint name="right_front_hip_joint">
      <hardwareInterface>hardware_interface/PositionJointInterface</hardwareInterface>
    </joint>
    <actuator name="right_front_hip_motor">
      <hardwareInterface>hardware_interface/PositionJointInterface</hardwareInterface>
      <mechanicalReduction>1</mechanicalReduction>
    </actuator>
  </transmission>
  <transmission name="right_front_knee_trans">
    <type>transmission_interface/SimpleTransmission</type>
    <joint name="right_front_upper_leg_joint">
      <hardwareInterface>hardware_interface/PositionJointInterface</hardwareInterface>
    </joint>
    <actuator name="right_front_knee_motor">
      <hardwareInterface>hardware_interface/PositionJointInterface</hardwareInterface>
      <mechanicalReduction>1</mechanicalReduction>
    </actuator>
  </transmission>
  <transmission name="right_front_ankle_trans">
    <type>transmission_interface/SimpleTransmission</type>
    <joint name="right_front_lower_leg_joint">
      <hardwareInterface>hardware_interface/PositionJointInterface</hardwareInterface>
    </joint>
    <actuator name="right_front_ankle_motor">
      <hardwareInterface>hardware_interface/PositionJointInterface</hardwareInterface>
      <mechanicalReduction>1</mechanicalReduction>
    </actuator>
  </transmission>
  <transmission name="left_rear_hip_trans">
    <type>transmission_interface/SimpleTransmission</type>
    <joint name="left_rear_hip_joint">
      <hardwareInterface>hardware_interface/PositionJointInterface</hardwareInterface>
    </joint>
    <actuator name="left_rear_hip_motor">
      <hardwareInterface>hardware_interface/PositionJointInterface</hardwareInterface>
      <mechanicalReduction>1</mechanicalReduction>
    </actuator>
  </transmission>
  <transmission name="left_rear_knee_trans">
    <type>transmission_interface/SimpleTransmission</type>
    <joint name="left_rear_upper_leg_joint">
      <hardwareInterface>hardware_interface/PositionJointInterface</hardwareInterface>
    </joint>
    <actuator name="left_rear_knee_motor">
      <hardwareInterface>hardware_interface/PositionJointInterface</hardwareInterface>
      <mechanicalReduction>1</mechanicalReduction>
    </actuator>
  </transmission>
  <transmission name="left_rear_ankle_trans">
    <type>transmission_interface/SimpleTransmission</type>
    <joint name="left_rear_lower_leg_joint">
      <hardwareInterface>hardware_interface/PositionJointInterface</hardwareInterface>
    </joint>
    <actuator name="left_rear_ankle_motor">
      <hardwareInterface>hardware_interface/PositionJointInterface</hardwareInterface>
      <mechanicalReduction>1</mechanicalReduction>
    </actuator>
  </transmission>
  <transmission name="right_rear_hip_trans">
    <type>transmission_interface/SimpleTransmission</type>
    <joint name="right_rear_hip_joint">
      <hardwareInterface>hardware_interface/PositionJointInterface</hardwareInterface>
    </joint>
    <actuator name="right_rear_hip_motor">
      <hardwareInterface>hardware_interface/PositionJointInterface</hardwareInterface>
      <mechanicalReduction>1</mechanicalReduction>
    </actuator>
  </transmission>
  <transmission name="right_rear_knee_trans">
    <type>transmission_interface/SimpleTransmission</type>
    <joint name="right_rear_upper_leg_joint">
      <hardwareInterface>hardware_interface/PositionJointInterface</hardwareInterface>
    </joint>
    <actuator name="right_rear_knee_motor">
      <hardwareInterface>hardware_interface/PositionJointInterface</hardwareInterface>
      <mechanicalReduction>1</mechanicalReduction>
    </actuator>
  </transmission>
  <transmission name="right_rear_ankle_trans">
    <type>transmission_interface/SimpleTransmission</type>
    <joint name="right_rear_lower_leg_joint">
      <hardwareInterface>hardware_interface/PositionJointInterface</hardwareInterface>
    </joint>
    <actuator name="right_rear_ankle_motor">
      <hardwareInterface>hardware_interface/PositionJointInterface</hardwareInterface>
      <mechanicalReduction>1</mechanicalReduction>
    </actuator>
  </transmission>
  <!-- HEAD LINK -->
  <joint name="head_joint" type="fixed">
    <parent link="base_link"/>
    <child link="head"/>
    <origin xyz="0 0 0.15"/>
  </joint>
  <link name="head">
    <visual>
      <origin xyz="0 0 0.05"/>
      <geometry>
        <box size="0.1 0.1 0.1"/>
      </geometry>
      <material name="orange"/>
    </visual>
    <collision>
      <origin xyz="0 0 0.05"/>
      <geometry>
        <box size="0.1 0.1 0.1"/>
      </geometry>
    </collision>
    <inertial>
      <origin rpy="0 0 0" xyz="0 0 0.05"/>
      <mass value="0.2"/>
      <inertia ixx="0.0003333333333333334" ixy="0.0" ixz="0.0" iyy="0.0003333333333333334" iyz="0.0" izz="0.0003333333333333334"/>
    </inertial>
  </link>
  <ros2_control name="FirstRobot" type="system">
    <hardware>
      <plugin>gz_ros2_control/GazeboSimSystem</plugin>
    </hardware>
    <joint name="left_front_hip_joint">
      <command_interface name="position"/>
      <state_interface name="position"/>
      <state_interface name="velocity"/>
    </joint>
    <joint name="left_front_upper_leg_joint">
      <command_interface name="position"/>
      <state_interface name="position"/>
      <state_interface name="velocity"/>
    </joint>
    <joint name="left_front_lower_leg_joint">
      <command_interface name="position"/>
      <state_interface name="position"/>
      <state_interface name="velocity"/>
    </joint>
    <joint name="right_front_hip_joint">
      <command_interface name="position"/>
      <state_interface name="position"/>
      <state_interface name="velocity"/>
    </joint>
    <joint name="right_front_upper_leg_joint">
      <command_interface name="position"/>
      <state_interface name="position"/>
      <state_interface name="velocity"/>
    </joint>
    <joint name="right_front_lower_leg_joint">
      <command_interface name="position"/>
      <state_interface name="position"/>
      <state_interface name="velocity"/>
    </joint>
    <joint name="left_rear_hip_joint">
      <command_interface name="position"/>
      <state_interface name="position"/>
      <state_interface name="velocity"/>
    </joint>
    <joint name="left_rear_upper_leg_joint">
      <command_interface name="position"/>
      <state_interface name="position"/>
      <state_interface name="velocity"/>
    </joint>
    <joint name="left_rear_lower_leg_joint">
      <command_interface name="position"/>
      <state_interface name="position"/>
      <state_interface name="velocity"/>
    </joint>
    <joint name="right_rear_hip_joint">
      <command_interface name="position"/>
      <state_interface name="position"/>
      <state_interface name="velocity"/>
    </joint>
    <joint name="right_rear_upper_leg_joint">
      <command_interface name="position"/>
      <state_interface name="position"/>
      <state_interface name="velocity"/>
    </joint>
    <joint name="right_rear_lower_leg_joint">
      <command_interface name="position"/>
      <state_interface name="position"/>
      <state_interface name="velocity"/>
    </joint>
  </ros2_control>
  <gazebo>
    <plugin filename="gz_ros2_control-system" name="gz_ros2_control::GazeboSimROS2ControlPlugin">
      <parameters>/home/phieu/ros2-learning/src/install/first_robot/share/first_robot/config/ros_control.yaml</parameters>
    </plugin>
  </gazebo>
  <joint name="laser_joint" type="fixed">
    <parent link="base_link"/>
    <child link="lidar_link"/>
    <origin rpy="0 0 0" xyz="0.1 0 0.175"/>
  </joint>
  <link name="lidar_link">
    <visual>
      <geometry>
        <cylinder length="0.04" radius="0.05"/>
      </geometry>
      <material name="red"/>
    </visual>
    <collision>
      <geometry>
        <cylinder length="0.04" radius="0.05"/>
      </geometry>
    </collision>
    <inertial>
      <origin rpy="0 0 0" xyz="0 0 0"/>
      <mass value="0.1"/>
      <inertia ixx="7.583333333333335e-05" ixy="0.0" ixz="0.0" iyy="7.583333333333335e-05" iyz="0.0" izz="0.00012500000000000003"/>
    </inertial>
  </link>
  <gazebo reference="lidar_link">
    <sensor name="lidar_link" type="gpu_lidar">
      <always_on>true</always_on>
      <update_rate>2</update_rate>
      <topic>/scan</topic>
      <visualize>true</visualize>
      <frame_id>lidar_link</frame_id>
      <gz_frame_id>lidar_link</gz_frame_id>
      <ign_frame_id>lidar_link</ign_frame_id>
      <ros>
        <namespace>/</namespace>
        <remapping>scan:=scan</remapping>
      </ros>
      <ray>
        <scan>
          <horizontal>
            <samples>720</samples>
            <resolution>1</resolution>
            <min_angle>-1.5708</min_angle>
            <max_angle>1.5708</max_angle>
          </horizontal>
        </scan>
        <range>
          <min>0.1</min>
          <max>10.0</max>
        </range>
        <noise>
          <type>gaussian</type>
          <mean>0.0</mean>
          <stddev>0.01</stddev>
        </noise>
      </ray>
      <!-- <plugin
                filename="gz-sim-sensors-system"
                name="gz::sim::systems::Sensors">
                <render_engine>ogre</render_engine>
            </plugin> -->
    </sensor>
  </gazebo>
  <joint name="camera_joint" type="fixed">
    <parent link="chassis"/>
    <child link="camera_link"/>
    <origin rpy="0 0 0" xyz="0.25 0 0.08"/>
  </joint>
  <joint name="camera_optical_joint" type="fixed">
    <parent link="camera_link"/>
    <child link="camera_link_optical"/>
    <origin rpy="-1.5707963267948966 0 -1.5707963267948966" xyz="0.25 0 0"/>
  </joint>
  <link name="camera_link_optical"/>
  <link name="camera_link">
    <visual>
      <geometry>
        <box size="0.010 0.03 0.03"/>
      </geometry>
      <material name="red"/>
    </visual>
  </link>
  <gazebo reference="camera_link">
    <material>Gazebo/Red</material>
    <sensor name="camera" type="camera">
      <camera>
        <horizontal_fov>1.047</horizontal_fov>
        <image>
          <width>320</width>
          <height>240</height>
        </image>
        <clip>
          <near>0.1</near>
          <far>100</far>
        </clip>
      </camera>
      <always_on>1</always_on>
      <update_rate>30</update_rate>
      <visualize>true</visualize>
      <topic>camera</topic>
    </sensor>
  </gazebo>
  <link name="imu_link">
    <inertial>
      <mass value="0.01"/>
      <origin xyz="0 0 0"/>
      <inertia ixx="0.001" ixy="0" ixz="0" iyy="0.001" iyz="0" izz="0.001"/>
    </inertial>
  </link>
  <joint name="imu_joint" type="fixed">
    <parent link="base_link"/>
    <child link="imu_link"/>
    <origin xyz="0 0 0.1"/>
    <!-- Đặt IMU gần trọng tâm -->
  </joint>
  <gazebo reference="imu_link">
    <sensor name="imu_sensor" type="imu">
      <always_on>true</always_on>
      <update_rate>200</update_rate>
      <topic>imu/data</topic>
      <plugin filename="gz-sim-imu-system" name="gz::sim::systems::Imu">
        <ros>
          <namespace>/</namespace>
        </ros>
      </plugin>
      <imu>
        <noise type="gaussian">
          <rate>
            <mean>0.0</mean>
            <stddev>0.005</stddev>
            <!-- Giảm nhiễu -->
          </rate>
          <accel>
            <mean>0.0</mean>
            <stddev>0.005</stddev>
          </accel>
        </noise>
      </imu>
    </sensor>
  </gazebo>
</robot>
