<?xml version="1.0" ?>
<!-- =================================================================================== -->
<!-- |    This document was autogenerated by xacro from first_robot/description/robot.urdf.xacro | -->
<!-- |    EDITING THIS FILE BY HAND IS NOT RECOMMENDED                                 | -->
<!-- =================================================================================== -->
<robot name="my_robot">
  <material name="white">
    <color rgba="1 1 1 1"/>
  </material>
  <material name="orange">
    <color rgba="1 0.3 0.1 1"/>
  </material>
  <material name="blue">
    <color rgba="0 0 1 1"/>
  </material>
  <material name="green">
    <color rgba="0 1 0 1"/>
  </material>
  <material name="yellow">
    <color rgba="1 1 0 1"/>
  </material>
  <material name="cyan">
    <color rgba="0 1 1 1"/>
  </material>
  <material name="pink">
    <color rgba="1 0.5 0.5 1"/>
  </material>
  <material name="purple">
    <color rgba="0.5 0 0.5 1"/>
  </material>
  <material name="black">
    <color rgba="0 0 0 1"/>
  </material>
  <material name="red">
    <color rgba="1 0 0 1"/>
  </material>
  <material name="grey">
    <color rgba="0.5 0.5 0.5 1"/>
  </material>
  <material name="silver">
    <color rgba="0.75 0.75 0.75 1"/>
  </material>
  <!-- BASE LINK -->
  <link name="base_link">
    <visual name="base_link_visual">
      <origin xyz="0 0 0.0125"/>
      <geometry>
        <box size="0.2 0.15 0.05"/>
      </geometry>
      <material name="white"/>
    </visual>
    <collision name="base_link_collision">
      <origin xyz="0 0 0.025"/>
      <!-- Sửa tâm va chạm -->
      <geometry>
        <box size="0.2 0.15 0.05"/>
      </geometry>
    </collision>
    <inertial>
      <origin rpy="0 0 0" xyz="0 0 0.025"/>
      <mass value="0.5"/>
      <inertia ixx="0.0010416666666666667" ixy="0.0" ixz="0.0" iyy="0.0017708333333333337" iyz="0.0" izz="0.0026041666666666665"/>
    </inertial>
  </link>
  <!-- Front Body -->
  <link name="front_body">
    <visual name="front_body_visual">
      <geometry>
        <box size="0.05 0.1 0.05"/>
      </geometry>
      <material name="pink"/>
    </visual>
    <collision name="front_body_collision">
      <geometry>
        <box size="0.05 0.1 0.025"/>
      </geometry>
    </collision>
    <inertial>
      <mass value="1.0"/>
      <inertia ixx="0.01" ixy="0" ixz="0" iyy="0.01" iyz="0" izz="0.01"/>
    </inertial>
  </link>
  <!-- Joint nối base_link và front_body -->
  <joint name="front_body_joint" type="fixed">
    <parent link="base_link"/>
    <child link="front_body"/>
    <origin rpy="0 0 0" xyz="0.1 0 0"/>
    <!-- Đẩy về trước cho cân đối -->
  </joint>
  <!-- Rear Body -->
  <link name="rear_body">
    <visual name="rear_body_visual">
      <geometry>
        <box size="0.02 0.02 0.1"/>
      </geometry>
      <material name="purple"/>
    </visual>
    <collision name="rear_body_collision">
      <geometry>
        <box size="0.02 0.02 0.1"/>
      </geometry>
    </collision>
    <inertial>
      <mass value="2.0"/>
      <inertia ixx="0.01" ixy="0" ixz="0" iyy="0.01" iyz="0" izz="0.01"/>
    </inertial>
  </link>
  <!-- Joint nối base_link và rear_body -->
  <joint name="rear_body_joint" type="fixed">
    <parent link="base_link"/>
    <child link="rear_body"/>
    <origin rpy="0 0 0" xyz="-0.1 0 0"/>
    <!-- Đẩy về sau cho cân đối -->
  </joint>
  <!-- bắt đầu phần háng -->
  <!-- Hip Link -->
  <link name="front_left_hip_link">
    <visual name="front_left_hip_visual">
      <origin rpy="0 0 0" xyz="0 0.055 0"/>
      <!-- vị trí đặt link - khớp háng so với body -->
      <geometry>
        <box size="0.03 0.03 0.02"/>
        <!-- dài 2cm, cố định thân trên và các chân -->
      </geometry>
      <material name="blue"/>
    </visual>
    <collision name="front_left_hip_collision">
      <geometry>
        <box size="0.03 0.03 0.02"/>
        <!-- dài 2cm, cố định thân trên và các chân -->
      </geometry>
    </collision>
    <inertial>
      <mass value="0.2"/>
      <inertia ixx="0.000833" ixy="0.0" ixz="0.0" iyy="0.000833" iyz="0.0" izz="0.001666"/>
    </inertial>
  </link>
  <joint name="front_left_hip_joint" type="revolute">
    <parent link="front_body"/>
    <child link="front_left_hip_link"/>
    <origin rpy="0 0 0" xyz="0 0 0.0"/>
    <limit effort="30" lower="-1.57" upper="1.57" velocity="7.0"/>
    <!-- Vị trí gắn khớp háng vào body-->
  </joint>
  <!-- x1.1 Motor link vỏ motor mô phỏng, không quay -->
  <link name="front_left_hip_motor_link">
    <visual name="front_left_hip_motor_visual">
      <geometry>
        <cylinder length="0.02" radius="0.015"/>
      </geometry>
      <origin rpy="1.0 0 0" xyz="0.005 0 0"/>
      <origin rpy="1.5708 0 0" xyz="0.005 0.055 0"/>
      <!-- vị trí đặt link mô phỏng motor khớp háng- trái -->
      <material name="yellow"/>
    </visual>
    <inertial>
      <mass value="0.5"/>
      <inertia ixx="0.000417" ixy="0.0" ixz="0.0" iyy="0.000417" iyz="0.0" izz="0.000833"/>
    </inertial>
  </link>
  <!-- x1.2 Gắn motor link mô phỏng vào body bằng joint cố định -->
  <joint name="front_left_hip_motor_fixed" type="fixed">
    <parent link="front_left_hip_link"/>
    <child link="front_left_hip_motor_link"/>
    <origin rpy="0 0 0" xyz="0 0 0.0"/>
    <!-- Vị trí gắn motor -->
  </joint>
  <!-- Kết thúc phần háng -->
  <!-- *** Bắt đầu phần đùi chân *** -->
  <!-- knee Link -->
  <link name="front_left_knee_link">
    <visual name="front_left_knee_visual">
      <origin rpy="0 0 0" xyz="0.005 0.055 -0.05"/>
      <!-- Vị trí đặt link đùi -  so với motor háng mô phỏng -->
      <geometry>
        <cylinder length="0.1" radius="0.01"/>
      </geometry>
      <material name="green"/>
    </visual>
    <collision name="front_left_knee_collision">
      <geometry>
        <cylinder length="0.1" radius="0.01"/>
      </geometry>
    </collision>
    <inertial>
      <mass value="0.5"/>
      <inertia ixx="0.000417" ixy="0.0" ixz="0.0" iyy="0.000417" iyz="0.0" izz="0.000833"/>
    </inertial>
  </link>
  <!-- knee Joint (Đùi, quay về sau ) -->
  <joint name="front_left_knee_joint" type="revolute">
    <parent link="front_left_hip_motor_link"/>
    <!-- Gắn vào motor háng mô phỏng -->
    <child link="front_left_knee_link"/>
    <origin rpy="0.3 0.1 0" xyz="0 0 0"/>
    <!-- Vị trí đặt link đùi -  so với motor háng mô phỏng -->
    <axis xyz="0 1 0"/>
    <limit effort="30" lower="-1.57" upper="1.57" velocity="7.0"/>
  </joint>
  <!-- x2.1 Motor link vỏ motor mô phỏng Đầu gối , không quay -->
  <link name="front_left_knee_motor_link">
    <visual name="front_left_knee_motor_visual">
      <geometry>
        <cylinder length="0.02" radius="0.015"/>
      </geometry>
      <origin rpy="1.0 0 0" xyz="0.01 0.055 -0.085"/>
      <!-- vị trí đặt link mô phỏng motor khớp háng- trái -->
      <material name="red"/>
    </visual>
    <inertial>
      <mass value="0.5"/>
      <inertia ixx="0.000417" ixy="0.0" ixz="0.0" iyy="0.000417" iyz="0.0" izz="0.000833"/>
    </inertial>
  </link>
  <!-- x2.2 Gắn motor link mô phỏng vào body bằng joint cố định -->
  <joint name="front_left_knee_motor_fixed" type="fixed">
    <parent link="front_left_knee_link"/>
    <child link="front_left_knee_motor_link"/>
    <origin rpy="0 0 0" xyz="0 0 -0.01"/>
    <!-- Vị trí gắn motor -->
  </joint>
  <!-- *** Kết thúc phần đùi chân *** -->
  <!-- *** Bắt đầu phần cẳng chân *** -->
  <!-- ankle Link -->
  <link name="front_left_ankle_link">
    <visual name="front_left_ankle_visual">
      <geometry>
        <cylinder length="0.1" radius="0.01"/>
      </geometry>
      <origin rpy="0 -0.9 0" xyz="0 0 -0.12"/>
      <!-- Dịch xuống 1/2 chiều dài -->
      <!-- vị trí đặt link mô phỏng motor khớp háng- trái -->
      <material name="purple"/>
    </visual>
    <collision name="front_left_ankle_collision">
      <origin xyz="0 0 -0.12"/>
      <!-- Khớp visual -->
      <geometry>
        <cylinder length="0.1" radius="0.01"/>
      </geometry>
    </collision>
    <inertial>
      <origin xyz="0 0 -0.12"/>
      <!-- Dịch khối lượng xuống luôn -->
      <mass value="0.2"/>
      <inertia ixx="0.000417" ixy="0.0" ixz="0.0" iyy="0.000417" iyz="0.0" izz="0.000833"/>
    </inertial>
  </link>
  <!-- ankle Joint (Cẳng chân, quay về trước 45°) -->
  <joint name="front_left_ankle_joint" type="revolute">
    <parent link="front_left_knee_motor_link"/>
    <child link="front_left_ankle_link"/>
    <origin rpy="0.12 0.45 0" xyz="0.08 0.04 0"/>
    <!-- Vị trí đặt link đùi -  so với motor háng mô phỏng -->
    <!-- rút ngắn chiều dài -->
    <axis xyz="1 1 0"/>
    <limit effort="30" lower="-1.57" upper="1.57" velocity="7.0"/>
  </joint>
  <!-- *** Kết thúc phần cẳng chân *** -->
  <!-- Foot Link -->
  <link name="front_left_foot_link">
    <visual name="front_left_foot_visual">
      <origin xyz="0.045 0 -0.1"/>
      <geometry>
        <sphere radius="0.02"/>
      </geometry>
      <material name="black"/>
    </visual>
    <collision name="front_left_foot_collision">
      <origin xyz="0.045 0 -0.1"/>
      <geometry>
        <sphere radius="0.02"/>
      </geometry>
    </collision>
    <inertial>
      <mass value="0.05"/>
      <inertia ixx="0.000417" ixy="0.0" ixz="0.0" iyy="0.000417" iyz="0.0" izz="0.000833"/>
    </inertial>
  </link>
  <!-- Foot Joint -->
  <joint name="front_left_foot_joint" type="fixed">
    <parent link="front_left_ankle_link"/>
    <child link="front_left_foot_link"/>
    <origin rpy="0 0 0" xyz="0 0 -0.05"/>
    <!-- rút gọn lại -->
  </joint>
  <!-- Transmission cho các joint -->
  <transmission name="front_left_knee_trans">
    <type>transmission_interface/SimpleTransmission</type>
    <joint name="front_left_knee_joint"/>
    <actuator name="front_left_knee_motor">
      <mechanical_reduction>1</mechanical_reduction>
    </actuator>
  </transmission>
  <transmission name="front_left_ankle_trans">
    <type>transmission_interface/SimpleTransmission</type>
    <joint name="front_left_ankle_joint"/>
    <actuator name="front_left_ankle_motor">
      <mechanical_reduction>1</mechanical_reduction>
    </actuator>
  </transmission>
  <!-- bắt đầu phần háng -->
  <!-- Hip Link -->
  <link name="front_right_hip_link">
    <visual name="front_right_hip_visual">
      <origin rpy="0 0 0" xyz="0 -0.055 0"/>
      <!-- vị trí đặt link - khớp háng so với body -->
      <geometry>
        <box size="0.03 0.03 0.02"/>
        <!-- dài 2cm, cố định thân trên và các chân -->
      </geometry>
      <material name="blue"/>
    </visual>
    <collision name="front_right_hip_collision">
      <geometry>
        <box size="0.03 0.03 0.02"/>
        <!-- dài 2cm, cố định thân trên và các chân -->
      </geometry>
    </collision>
    <inertial>
      <mass value="0.2"/>
      <inertia ixx="0.000833" ixy="0.0" ixz="0.0" iyy="0.000833" iyz="0.0" izz="0.001666"/>
    </inertial>
  </link>
  <joint name="front_right_hip_joint" type="revolute">
    <parent link="front_body"/>
    <child link="front_right_hip_link"/>
    <origin rpy="0 0 0" xyz="0 0 0.0"/>
    <limit effort="30" lower="-1.57" upper="1.57" velocity="7.0"/>
    <!-- Vị trí gắn khớp háng vào body-->
  </joint>
  <!-- x1.1 Motor link vỏ motor mô phỏng, không quay -->
  <link name="front_right_hip_motor_link">
    <visual name="front_right_hip_motor_visual">
      <geometry>
        <cylinder length="0.02" radius="0.015"/>
      </geometry>
      <origin rpy="1.0 0 0" xyz="0.005 0 0"/>
      <origin rpy="1.5708 0 0" xyz="0.005 -0.055 0"/>
      <!-- vị trí đặt link mô phỏng motor khớp háng- phải -->
      <material name="yellow"/>
    </visual>
    <inertial>
      <mass value="0.5"/>
      <inertia ixx="0.000417" ixy="0.0" ixz="0.0" iyy="0.000417" iyz="0.0" izz="0.000833"/>
    </inertial>
  </link>
  <!-- x1.2 Gắn motor link mô phỏng vào body bằng joint cố định -->
  <joint name="front_right_hip_motor_fixed" type="fixed">
    <parent link="front_right_hip_link"/>
    <child link="front_right_hip_motor_link"/>
    <origin rpy="0 0 0" xyz="0 0 0.0"/>
    <!-- Vị trí gắn motor -->
  </joint>
  <!-- Kết thúc phần háng -->
  <!-- *** Bắt đầu phần đùi chân *** -->
  <!-- knee Link -->
  <link name="front_right_knee_link">
    <visual name="front_right_knee_visual">
      <origin rpy="0 0 0" xyz="0.005 -0.055 -0.05"/>
      <!-- Vị trí đặt link đùi -  so với motor háng mô phỏng -->
      <geometry>
        <cylinder length="0.1" radius="0.01"/>
      </geometry>
      <material name="green"/>
    </visual>
    <collision name="front_right_knee_collision">
      <geometry>
        <cylinder length="0.1" radius="0.01"/>
      </geometry>
    </collision>
    <inertial>
      <mass value="0.5"/>
      <inertia ixx="0.000417" ixy="0.0" ixz="0.0" iyy="0.000417" iyz="0.0" izz="0.000833"/>
    </inertial>
  </link>
  <!-- knee Joint (Đùi, quay về sau ) -->
  <joint name="front_right_knee_joint" type="revolute">
    <parent link="front_right_hip_motor_link"/>
    <!-- Gắn vào motor háng mô phỏng -->
    <child link="front_right_knee_link"/>
    <origin rpy="-0.3 0.1 0" xyz="0 0 0"/>
    <!-- Vị trí đặt link đùi -  so với motor háng mô phỏng -->
    <axis xyz="0 1 0"/>
    <limit effort="30" lower="-1.57" upper="1.57" velocity="7.0"/>
  </joint>
  <!-- x2.1 Motor link vỏ motor mô phỏng Đầu gối , không quay -->
  <link name="front_right_knee_motor_link">
    <visual name="front_right_knee_motor_visual">
      <geometry>
        <cylinder length="0.02" radius="0.015"/>
      </geometry>
      <origin rpy="1.0 0 0" xyz="0.01 -0.055 -0.085"/>
      <!-- vị trí đặt link mô phỏng motor khớp háng- phải -->
      <material name="red"/>
    </visual>
    <inertial>
      <mass value="0.5"/>
      <inertia ixx="0.000417" ixy="0.0" ixz="0.0" iyy="0.000417" iyz="0.0" izz="0.000833"/>
    </inertial>
  </link>
  <!-- x2.2 Gắn motor link mô phỏng vào body bằng joint cố định -->
  <joint name="front_right_knee_motor_fixed" type="fixed">
    <parent link="front_right_knee_link"/>
    <child link="front_right_knee_motor_link"/>
    <origin rpy="0 0 0" xyz="0 0 -0.01"/>
    <!-- Vị trí gắn motor -->
  </joint>
  <!-- *** Kết thúc phần đùi chân *** -->
  <!-- *** Bắt đầu phần cẳng chân *** -->
  <!-- ankle Link -->
  <link name="front_right_ankle_link">
    <visual name="front_right_ankle_visual">
      <geometry>
        <cylinder length="0.1" radius="0.01"/>
      </geometry>
      <origin rpy="0 -0.9 0" xyz="0 0 -0.12"/>
      <!-- Dịch xuống 1/2 chiều dài -->
      <!-- vị trí đặt link mô phỏng motor khớp háng- phải -->
      <material name="purple"/>
    </visual>
    <collision name="front_right_ankle_collision">
      <origin xyz="0 0 -0.12"/>
      <!-- Khớp visual -->
      <geometry>
        <cylinder length="0.1" radius="0.01"/>
      </geometry>
    </collision>
    <inertial>
      <origin xyz="0 0 -0.12"/>
      <!-- Dịch khối lượng xuống luôn -->
      <mass value="0.2"/>
      <inertia ixx="0.000417" ixy="0.0" ixz="0.0" iyy="0.000417" iyz="0.0" izz="0.000833"/>
    </inertial>
  </link>
  <!-- ankle Joint (Cẳng chân, quay về trước 45°) -->
  <joint name="front_right_ankle_joint" type="revolute">
    <parent link="front_right_knee_motor_link"/>
    <child link="front_right_ankle_link"/>
    <origin rpy="-0.12 0.45 0" xyz="0.08 -0.04 0"/>
    <!-- Vị trí đặt link đùi -  so với motor háng mô phỏng -->
    <!-- rút ngắn chiều dài -->
    <axis xyz="1 1 0"/>
    <limit effort="30" lower="-1.57" upper="1.57" velocity="7.0"/>
  </joint>
  <!-- *** Kết thúc phần cẳng chân *** -->
  <!-- Foot Link -->
  <link name="front_right_foot_link">
    <visual name="front_right_foot_visual">
      <origin xyz="0.045 0 -0.1"/>
      <geometry>
        <sphere radius="0.02"/>
      </geometry>
      <material name="black"/>
    </visual>
    <collision name="front_right_foot_collision">
      <origin xyz="0.045 0 -0.1"/>
      <geometry>
        <sphere radius="0.02"/>
      </geometry>
    </collision>
    <inertial>
      <mass value="0.05"/>
      <inertia ixx="0.000417" ixy="0.0" ixz="0.0" iyy="0.000417" iyz="0.0" izz="0.000833"/>
    </inertial>
  </link>
  <!-- Foot Joint -->
  <joint name="front_right_foot_joint" type="fixed">
    <parent link="front_right_ankle_link"/>
    <child link="front_right_foot_link"/>
    <origin rpy="0 0 0" xyz="0 0 -0.05"/>
    <!-- rút gọn lại -->
  </joint>
  <!-- Transmission cho các joint -->
  <transmission name="front_right_knee_trans">
    <type>transmission_interface/SimpleTransmission</type>
    <joint name="front_right_knee_joint"/>
    <actuator name="front_right_knee_motor">
      <mechanical_reduction>1</mechanical_reduction>
    </actuator>
  </transmission>
  <transmission name="front_right_ankle_trans">
    <type>transmission_interface/SimpleTransmission</type>
    <joint name="front_right_ankle_joint"/>
    <actuator name="front_right_ankle_motor">
      <mechanical_reduction>1</mechanical_reduction>
    </actuator>
  </transmission>
  <!-- bắt đầu phần háng -->
  <!-- Hip Link -->
  <link name="rear_left_hip_link">
    <visual name="rear_left_hip_visual">
      <origin rpy="0 0 0" xyz="0 0.055 0"/>
      <!-- vị trí đặt link - khớp háng so với body -->
      <geometry>
        <box size="0.03 0.03 0.02"/>
        <!-- dài 2cm, cố định thân trên và các chân -->
      </geometry>
      <material name="blue"/>
    </visual>
    <collision name="rear_left_hip_collision">
      <geometry>
        <box size="0.03 0.03 0.02"/>
        <!-- dài 2cm, cố định thân trên và các chân -->
      </geometry>
    </collision>
    <inertial>
      <mass value="0.2"/>
      <inertia ixx="0.000833" ixy="0.0" ixz="0.0" iyy="0.000833" iyz="0.0" izz="0.001666"/>
    </inertial>
  </link>
  <joint name="rear_left_hip_joint" type="revolute">
    <parent link="rear_body"/>
    <child link="rear_left_hip_link"/>
    <origin rpy="0 0 0" xyz="0 0 0.0"/>
    <limit effort="30" lower="-1.57" upper="1.57" velocity="7.0"/>
    <!-- Vị trí gắn khớp háng vào body-->
  </joint>
  <!-- x1.1 Motor link vỏ motor mô phỏng, không quay -->
  <link name="rear_left_hip_motor_link">
    <visual name="rear_left_hip_motor_visual">
      <geometry>
        <cylinder length="0.02" radius="0.015"/>
      </geometry>
      <origin rpy="1.0 0 0" xyz="0.005 0 0"/>
      <origin rpy="1.5708 0 0" xyz="0.005 0.055 0"/>
      <!-- vị trí đặt link mô phỏng motor khớp háng- trái -->
      <material name="yellow"/>
    </visual>
    <inertial>
      <mass value="0.5"/>
      <inertia ixx="0.000417" ixy="0.0" ixz="0.0" iyy="0.000417" iyz="0.0" izz="0.000833"/>
    </inertial>
  </link>
  <!-- x1.2 Gắn motor link mô phỏng vào body bằng joint cố định -->
  <joint name="rear_left_hip_motor_fixed" type="fixed">
    <parent link="rear_left_hip_link"/>
    <child link="rear_left_hip_motor_link"/>
    <origin rpy="0 0 0" xyz="0 0 0.0"/>
    <!-- Vị trí gắn motor -->
  </joint>
  <!-- Kết thúc phần háng -->
  <!-- *** Bắt đầu phần đùi chân *** -->
  <!-- knee Link -->
  <link name="rear_left_knee_link">
    <visual name="rear_left_knee_visual">
      <origin rpy="0 0 0" xyz="0.005 0.055 -0.05"/>
      <!-- Vị trí đặt link đùi -  so với motor háng mô phỏng -->
      <geometry>
        <cylinder length="0.1" radius="0.01"/>
      </geometry>
      <material name="green"/>
    </visual>
    <collision name="rear_left_knee_collision">
      <geometry>
        <cylinder length="0.1" radius="0.01"/>
      </geometry>
    </collision>
    <inertial>
      <mass value="0.5"/>
      <inertia ixx="0.000417" ixy="0.0" ixz="0.0" iyy="0.000417" iyz="0.0" izz="0.000833"/>
    </inertial>
  </link>
  <!-- knee Joint (Đùi, quay về sau ) -->
  <joint name="rear_left_knee_joint" type="revolute">
    <parent link="rear_left_hip_motor_link"/>
    <!-- Gắn vào motor háng mô phỏng -->
    <child link="rear_left_knee_link"/>
    <origin rpy="0.3 0.1 0" xyz="0 0 0"/>
    <!-- Vị trí đặt link đùi -  so với motor háng mô phỏng -->
    <axis xyz="0 1 0"/>
    <limit effort="30" lower="-1.57" upper="1.57" velocity="7.0"/>
  </joint>
  <!-- x2.1 Motor link vỏ motor mô phỏng Đầu gối , không quay -->
  <link name="rear_left_knee_motor_link">
    <visual name="rear_left_knee_motor_visual">
      <geometry>
        <cylinder length="0.02" radius="0.015"/>
      </geometry>
      <origin rpy="1.0 0 0" xyz="0.01 0.055 -0.085"/>
      <!-- vị trí đặt link mô phỏng motor khớp háng- trái -->
      <material name="red"/>
    </visual>
    <inertial>
      <mass value="0.5"/>
      <inertia ixx="0.000417" ixy="0.0" ixz="0.0" iyy="0.000417" iyz="0.0" izz="0.000833"/>
    </inertial>
  </link>
  <!-- x2.2 Gắn motor link mô phỏng vào body bằng joint cố định -->
  <joint name="rear_left_knee_motor_fixed" type="fixed">
    <parent link="rear_left_knee_link"/>
    <child link="rear_left_knee_motor_link"/>
    <origin rpy="0 0 0" xyz="0 0 -0.01"/>
    <!-- Vị trí gắn motor -->
  </joint>
  <!-- *** Kết thúc phần đùi chân *** -->
  <!-- *** Bắt đầu phần cẳng chân *** -->
  <!-- ankle Link -->
  <link name="rear_left_ankle_link">
    <visual name="rear_left_ankle_visual">
      <geometry>
        <cylinder length="0.1" radius="0.01"/>
      </geometry>
      <origin rpy="0 -0.9 0" xyz="0 0 -0.12"/>
      <!-- Dịch xuống 1/2 chiều dài -->
      <!-- vị trí đặt link mô phỏng motor khớp háng- trái -->
      <material name="purple"/>
    </visual>
    <collision name="rear_left_ankle_collision">
      <origin xyz="0 0 -0.12"/>
      <!-- Khớp visual -->
      <geometry>
        <cylinder length="0.1" radius="0.01"/>
      </geometry>
    </collision>
    <inertial>
      <origin xyz="0 0 -0.12"/>
      <!-- Dịch khối lượng xuống luôn -->
      <mass value="0.2"/>
      <inertia ixx="0.000417" ixy="0.0" ixz="0.0" iyy="0.000417" iyz="0.0" izz="0.000833"/>
    </inertial>
  </link>
  <!-- ankle Joint (Cẳng chân, quay về trước 45°) -->
  <joint name="rear_left_ankle_joint" type="revolute">
    <parent link="rear_left_knee_motor_link"/>
    <child link="rear_left_ankle_link"/>
    <origin rpy="0.12 0.45 0" xyz="0.08 0.04 0"/>
    <!-- Vị trí đặt link đùi -  so với motor háng mô phỏng -->
    <!-- rút ngắn chiều dài -->
    <axis xyz="1 1 0"/>
    <limit effort="30" lower="-1.57" upper="1.57" velocity="7.0"/>
  </joint>
  <!-- *** Kết thúc phần cẳng chân *** -->
  <!-- Foot Link -->
  <link name="rear_left_foot_link">
    <visual name="rear_left_foot_visual">
      <origin xyz="0.045 0 -0.1"/>
      <geometry>
        <sphere radius="0.02"/>
      </geometry>
      <material name="black"/>
    </visual>
    <collision name="rear_left_foot_collision">
      <origin xyz="0.045 0 -0.1"/>
      <geometry>
        <sphere radius="0.02"/>
      </geometry>
    </collision>
    <inertial>
      <mass value="0.05"/>
      <inertia ixx="0.000417" ixy="0.0" ixz="0.0" iyy="0.000417" iyz="0.0" izz="0.000833"/>
    </inertial>
  </link>
  <!-- Foot Joint -->
  <joint name="rear_left_foot_joint" type="fixed">
    <parent link="rear_left_ankle_link"/>
    <child link="rear_left_foot_link"/>
    <origin rpy="0 0 0" xyz="0 0 -0.05"/>
    <!-- rút gọn lại -->
  </joint>
  <!-- Transmission cho các joint -->
  <transmission name="rear_left_knee_trans">
    <type>transmission_interface/SimpleTransmission</type>
    <joint name="rear_left_knee_joint"/>
    <actuator name="rear_left_knee_motor">
      <mechanical_reduction>1</mechanical_reduction>
    </actuator>
  </transmission>
  <transmission name="rear_left_ankle_trans">
    <type>transmission_interface/SimpleTransmission</type>
    <joint name="rear_left_ankle_joint"/>
    <actuator name="rear_left_ankle_motor">
      <mechanical_reduction>1</mechanical_reduction>
    </actuator>
  </transmission>
  <!-- bắt đầu phần háng -->
  <!-- Hip Link -->
  <link name="rear_right_hip_link">
    <visual name="rear_right_hip_visual">
      <origin rpy="0 0 0" xyz="0 -0.055 0"/>
      <!-- vị trí đặt link - khớp háng so với body -->
      <geometry>
        <box size="0.03 0.03 0.02"/>
        <!-- dài 2cm, cố định thân trên và các chân -->
      </geometry>
      <material name="blue"/>
    </visual>
    <collision name="rear_right_hip_collision">
      <geometry>
        <box size="0.03 0.03 0.02"/>
        <!-- dài 2cm, cố định thân trên và các chân -->
      </geometry>
    </collision>
    <inertial>
      <mass value="0.2"/>
      <inertia ixx="0.000833" ixy="0.0" ixz="0.0" iyy="0.000833" iyz="0.0" izz="0.001666"/>
    </inertial>
  </link>
  <joint name="rear_right_hip_joint" type="revolute">
    <parent link="rear_body"/>
    <child link="rear_right_hip_link"/>
    <origin rpy="0 0 0" xyz="0 0 0.0"/>
    <limit effort="30" lower="-1.57" upper="1.57" velocity="7.0"/>
    <!-- Vị trí gắn khớp háng vào body-->
  </joint>
  <!-- x1.1 Motor link vỏ motor mô phỏng, không quay -->
  <link name="rear_right_hip_motor_link">
    <visual name="rear_right_hip_motor_visual">
      <geometry>
        <cylinder length="0.02" radius="0.015"/>
      </geometry>
      <origin rpy="1.0 0 0" xyz="0.005 0 0"/>
      <origin rpy="1.5708 0 0" xyz="0.005 -0.055 0"/>
      <!-- vị trí đặt link mô phỏng motor khớp háng- phải -->
      <material name="yellow"/>
    </visual>
    <inertial>
      <mass value="0.5"/>
      <inertia ixx="0.000417" ixy="0.0" ixz="0.0" iyy="0.000417" iyz="0.0" izz="0.000833"/>
    </inertial>
  </link>
  <!-- x1.2 Gắn motor link mô phỏng vào body bằng joint cố định -->
  <joint name="rear_right_hip_motor_fixed" type="fixed">
    <parent link="rear_right_hip_link"/>
    <child link="rear_right_hip_motor_link"/>
    <origin rpy="0 0 0" xyz="0 0 0.0"/>
    <!-- Vị trí gắn motor -->
  </joint>
  <!-- Kết thúc phần háng -->
  <!-- *** Bắt đầu phần đùi chân *** -->
  <!-- knee Link -->
  <link name="rear_right_knee_link">
    <visual name="rear_right_knee_visual">
      <origin rpy="0 0 0" xyz="0.005 -0.055 -0.05"/>
      <!-- Vị trí đặt link đùi -  so với motor háng mô phỏng -->
      <geometry>
        <cylinder length="0.1" radius="0.01"/>
      </geometry>
      <material name="green"/>
    </visual>
    <collision name="rear_right_knee_collision">
      <geometry>
        <cylinder length="0.1" radius="0.01"/>
      </geometry>
    </collision>
    <inertial>
      <mass value="0.5"/>
      <inertia ixx="0.000417" ixy="0.0" ixz="0.0" iyy="0.000417" iyz="0.0" izz="0.000833"/>
    </inertial>
  </link>
  <!-- knee Joint (Đùi, quay về sau ) -->
  <joint name="rear_right_knee_joint" type="revolute">
    <parent link="rear_right_hip_motor_link"/>
    <!-- Gắn vào motor háng mô phỏng -->
    <child link="rear_right_knee_link"/>
    <origin rpy="-0.3 0.1 0" xyz="0 0 0"/>
    <!-- Vị trí đặt link đùi -  so với motor háng mô phỏng -->
    <axis xyz="0 1 0"/>
    <limit effort="30" lower="-1.57" upper="1.57" velocity="7.0"/>
  </joint>
  <!-- x2.1 Motor link vỏ motor mô phỏng Đầu gối , không quay -->
  <link name="rear_right_knee_motor_link">
    <visual name="rear_right_knee_motor_visual">
      <geometry>
        <cylinder length="0.02" radius="0.015"/>
      </geometry>
      <origin rpy="1.0 0 0" xyz="0.01 -0.055 -0.085"/>
      <!-- vị trí đặt link mô phỏng motor khớp háng- phải -->
      <material name="red"/>
    </visual>
    <inertial>
      <mass value="0.5"/>
      <inertia ixx="0.000417" ixy="0.0" ixz="0.0" iyy="0.000417" iyz="0.0" izz="0.000833"/>
    </inertial>
  </link>
  <!-- x2.2 Gắn motor link mô phỏng vào body bằng joint cố định -->
  <joint name="rear_right_knee_motor_fixed" type="fixed">
    <parent link="rear_right_knee_link"/>
    <child link="rear_right_knee_motor_link"/>
    <origin rpy="0 0 0" xyz="0 0 -0.01"/>
    <!-- Vị trí gắn motor -->
  </joint>
  <!-- *** Kết thúc phần đùi chân *** -->
  <!-- *** Bắt đầu phần cẳng chân *** -->
  <!-- ankle Link -->
  <link name="rear_right_ankle_link">
    <visual name="rear_right_ankle_visual">
      <geometry>
        <cylinder length="0.1" radius="0.01"/>
      </geometry>
      <origin rpy="0 -0.9 0" xyz="0 0 -0.12"/>
      <!-- Dịch xuống 1/2 chiều dài -->
      <!-- vị trí đặt link mô phỏng motor khớp háng- phải -->
      <material name="purple"/>
    </visual>
    <collision name="rear_right_ankle_collision">
      <origin xyz="0 0 -0.12"/>
      <!-- Khớp visual -->
      <geometry>
        <cylinder length="0.1" radius="0.01"/>
      </geometry>
    </collision>
    <inertial>
      <origin xyz="0 0 -0.12"/>
      <!-- Dịch khối lượng xuống luôn -->
      <mass value="0.2"/>
      <inertia ixx="0.000417" ixy="0.0" ixz="0.0" iyy="0.000417" iyz="0.0" izz="0.000833"/>
    </inertial>
  </link>
  <!-- ankle Joint (Cẳng chân, quay về trước 45°) -->
  <joint name="rear_right_ankle_joint" type="revolute">
    <parent link="rear_right_knee_motor_link"/>
    <child link="rear_right_ankle_link"/>
    <origin rpy="-0.12 0.45 0" xyz="0.08 -0.04 0"/>
    <!-- Vị trí đặt link đùi -  so với motor háng mô phỏng -->
    <!-- rút ngắn chiều dài -->
    <axis xyz="1 1 0"/>
    <limit effort="30" lower="-1.57" upper="1.57" velocity="7.0"/>
  </joint>
  <!-- *** Kết thúc phần cẳng chân *** -->
  <!-- Foot Link -->
  <link name="rear_right_foot_link">
    <visual name="rear_right_foot_visual">
      <origin xyz="0.045 0 -0.1"/>
      <geometry>
        <sphere radius="0.02"/>
      </geometry>
      <material name="black"/>
    </visual>
    <collision name="rear_right_foot_collision">
      <origin xyz="0.045 0 -0.1"/>
      <geometry>
        <sphere radius="0.02"/>
      </geometry>
    </collision>
    <inertial>
      <mass value="0.05"/>
      <inertia ixx="0.000417" ixy="0.0" ixz="0.0" iyy="0.000417" iyz="0.0" izz="0.000833"/>
    </inertial>
  </link>
  <!-- Foot Joint -->
  <joint name="rear_right_foot_joint" type="fixed">
    <parent link="rear_right_ankle_link"/>
    <child link="rear_right_foot_link"/>
    <origin rpy="0 0 0" xyz="0 0 -0.05"/>
    <!-- rút gọn lại -->
  </joint>
  <!-- Transmission cho các joint -->
  <transmission name="rear_right_knee_trans">
    <type>transmission_interface/SimpleTransmission</type>
    <joint name="rear_right_knee_joint"/>
    <actuator name="rear_right_knee_motor">
      <mechanical_reduction>1</mechanical_reduction>
    </actuator>
  </transmission>
  <transmission name="rear_right_ankle_trans">
    <type>transmission_interface/SimpleTransmission</type>
    <joint name="rear_right_ankle_joint"/>
    <actuator name="rear_right_ankle_motor">
      <mechanical_reduction>1</mechanical_reduction>
    </actuator>
  </transmission>
  <ros2_control name="FirstRobot" type="system">
    <hardware>
      <plugin>gz_ros2_control/GazeboSimSystem</plugin>
    </hardware>
    <joint name="front_left_hip_joint">
      <command_interface name="position"/>
      <state_interface name="position"/>
      <state_interface name="velocity"/>
    </joint>
    <joint name="front_left_knee_joint">
      <command_interface name="position"/>
      <state_interface name="position"/>
      <state_interface name="velocity"/>
    </joint>
    <joint name="front_left_ankle_joint">
      <command_interface name="position"/>
      <state_interface name="position"/>
      <state_interface name="velocity"/>
    </joint>
    <joint name="front_right_hip_joint">
      <command_interface name="position"/>
      <state_interface name="position"/>
      <state_interface name="velocity"/>
    </joint>
    <joint name="front_right_knee_joint">
      <command_interface name="position"/>
      <state_interface name="position"/>
      <state_interface name="velocity"/>
    </joint>
    <joint name="front_right_ankle_joint">
      <command_interface name="position"/>
      <state_interface name="position"/>
      <state_interface name="velocity"/>
    </joint>
    <joint name="rear_left_hip_joint">
      <command_interface name="position"/>
      <state_interface name="position"/>
      <state_interface name="velocity"/>
    </joint>
    <joint name="rear_left_knee_joint">
      <command_interface name="position"/>
      <state_interface name="position"/>
      <state_interface name="velocity"/>
    </joint>
    <joint name="rear_left_ankle_joint">
      <command_interface name="position"/>
      <state_interface name="position"/>
      <state_interface name="velocity"/>
    </joint>
    <joint name="rear_right_hip_joint">
      <command_interface name="position"/>
      <state_interface name="position"/>
      <state_interface name="velocity"/>
    </joint>
    <joint name="rear_right_knee_joint">
      <command_interface name="position"/>
      <state_interface name="position"/>
      <state_interface name="velocity"/>
    </joint>
    <joint name="rear_right_ankle_joint">
      <command_interface name="position"/>
      <state_interface name="position"/>
      <state_interface name="velocity"/>
    </joint>
  </ros2_control>
  <gazebo>
    <plugin filename="gz_ros2_control-system" name="gz_ros2_control::GazeboSimROS2ControlPlugin">
      <parameters>/home/phieu/ros2-learning/src/install/first_robot/share/first_robot/config/ros_control.yaml</parameters>
    </plugin>
  </gazebo>
  <joint name="laser_joint" type="fixed">
    <parent link="base_link"/>
    <child link="lidar_link"/>
    <origin rpy="0 0 0" xyz="0.05 0 0.045"/>
  </joint>
  <link name="lidar_link">
    <visual>
      <geometry>
        <cylinder length="0.02" radius="0.025"/>
      </geometry>
      <material name="red"/>
    </visual>
    <collision>
      <geometry>
        <cylinder length="0.02" radius="0.025"/>
      </geometry>
    </collision>
    <inertial>
      <origin rpy="0 0 0" xyz="0 0 0"/>
      <mass value="0.01"/>
      <inertia ixx="6.5833333333333335e-06" ixy="0.0" ixz="0.0" iyy="6.5833333333333335e-06" iyz="0.0" izz="1.2500000000000002e-05"/>
    </inertial>
  </link>
  <gazebo reference="lidar_link">
    <sensor name="lidar_link" type="gpu_lidar">
      <always_on>true</always_on>
      <update_rate>2</update_rate>
      <topic>/scan</topic>
      <visualize>true</visualize>
      <frame_id>lidar_link</frame_id>
      <gz_frame_id>lidar_link</gz_frame_id>
      <ign_frame_id>lidar_link</ign_frame_id>
      <ros>
        <namespace>/</namespace>
        <remapping>scan:=scan</remapping>
      </ros>
      <ray>
        <scan>
          <horizontal>
            <samples>720</samples>
            <resolution>1</resolution>
            <min_angle>-1.5708</min_angle>
            <max_angle>1.5708</max_angle>
          </horizontal>
        </scan>
        <range>
          <min>0.1</min>
          <max>10.0</max>
        </range>
        <noise>
          <type>gaussian</type>
          <mean>0.0</mean>
          <stddev>0.01</stddev>
        </noise>
      </ray>
      <!-- <plugin
                filename="gz-sim-sensors-system"
                name="gz::sim::systems::Sensors">
                <render_engine>ogre</render_engine>
            </plugin> -->
    </sensor>
  </gazebo>
  <joint name="camera_joint" type="fixed">
    <parent link="base_link"/>
    <child link="camera_link"/>
    <origin rpy="0 0 0" xyz="0.10 0 0.04"/>
  </joint>
  <joint name="camera_optical_joint" type="fixed">
    <parent link="camera_link"/>
    <child link="camera_link_optical"/>
    <origin rpy="-1.5707963267948966 0 -1.5707963267948966" xyz="0.05 0 0"/>
  </joint>
  <link name="camera_link_optical"/>
  <link name="camera_link">
    <visual>
      <geometry>
        <box size="0.010 0.03 0.015"/>
      </geometry>
      <material name="red"/>
    </visual>
  </link>
  <gazebo reference="camera_link">
    <material>Gazebo/Red</material>
    <sensor name="camera" type="camera">
      <camera>
        <horizontal_fov>1.047</horizontal_fov>
        <image>
          <width>320</width>
          <height>240</height>
        </image>
        <clip>
          <near>0.1</near>
          <far>100</far>
        </clip>
      </camera>
      <always_on>1</always_on>
      <update_rate>30</update_rate>
      <visualize>true</visualize>
      <topic>camera</topic>
    </sensor>
  </gazebo>
  <link name="imu_link">
    <inertial>
      <mass value="0.01"/>
      <origin xyz="0 0 0"/>
      <inertia ixx="0.001" ixy="0" ixz="0" iyy="0.001" iyz="0" izz="0.001"/>
    </inertial>
  </link>
  <joint name="imu_joint" type="fixed">
    <parent link="base_link"/>
    <child link="imu_link"/>
    <origin xyz="0 0 0.05"/>
    <!-- Đặt IMU gần trọng tâm -->
  </joint>
  <gazebo reference="imu_link">
    <sensor name="imu_sensor" type="imu">
      <always_on>true</always_on>
      <update_rate>200</update_rate>
      <topic>imu/data</topic>
      <plugin filename="gz-sim-imu-system" name="gz::sim::systems::Imu">
        <ros>
          <namespace>/</namespace>
        </ros>
      </plugin>
      <imu>
        <noise type="gaussian">
          <rate>
            <mean>0.0</mean>
            <stddev>0.005</stddev>
            <!-- Giảm nhiễu -->
          </rate>
          <accel>
            <mean>0.0</mean>
            <stddev>0.005</stddev>
          </accel>
        </noise>
      </imu>
    </sensor>
  </gazebo>
</robot>
