<?xml version="1.0" ?>
<!-- =================================================================================== -->
<!-- |    This document was autogenerated by xacro from first_robot/description/robot.urdf.xacro | -->
<!-- |    EDITING THIS FILE BY HAND IS NOT RECOMMENDED                                 | -->
<!-- =================================================================================== -->
<robot name="my_robot">
  <material name="white">
    <color rgba="1 1 1 1"/>
  </material>
  <material name="blue">
    <color rgba="0 0 1 1"/>
  </material>
  <material name="green">
    <color rgba="0 1 0 1"/>
  </material>
  <material name="yellow">
    <color rgba="1 1 0 1"/>
  </material>
  <material name="cyan">
    <color rgba="0 1 1 1"/>
  </material>
  <material name="pink">
    <color rgba="1 0.5 0.5 1"/>
  </material>
  <material name="purple">
    <color rgba="0.5 0 0.5 1"/>
  </material>
  <material name="black">
    <color rgba="0 0 0 1"/>
  </material>
  <material name="silver">
    <color rgba="0.9137254901960784 0.9137254901960784 0.8470588235294118 1.0"/>
  </material>
  <material name="orange">
    <color rgba="1.0 0.4235294117647059 0.0392156862745098 1.0"/>
  </material>
  <material name="brown">
    <color rgba="0.8705882352941177 0.8117647058823529 0.7647058823529411 1.0"/>
  </material>
  <material name="red">
    <color rgba="0.8 0.0 0.0 1.0"/>
  </material>
  <!-- Base -->
  <link name="base_link">
    <visual name="base_link_visual">
      <origin rpy="0 0 0" xyz="0 0 0"/>
      <geometry>
        <box size="0.001 0.001 0.001"/>
      </geometry>
      <material name="white"/>
    </visual>
    <inertial>
      <origin xyz="0 0 0"/>
      <mass value="0.1"/>
      <inertia ixx="0.001" ixy="0" ixz="0" iyy="0.001" iyz="0" izz="0.001"/>
    </inertial>
  </link>
  <joint name="floating_base" type="fixed">
    <parent link="base_link"/>
    <child link="trunk"/>
    <origin rpy="0 0 0" xyz="0 0 0"/>
  </joint>
  <!-- Trunk  Thân robot -->
  <link name="trunk">
    <visual name="trunk_visual">
      <origin rpy="0 0 0" xyz="0 0 0"/>
      <geometry>
        <!-- <box size="${trunk_length} ${trunk_width} ${trunk_height}"/> -->
        <mesh filename="file:///home/phieu/ros2-learning/src/install/first_robot/share/first_robot/meshes/trunk.dae" scale="1 1 1"/>
      </geometry>
      <material name="silver"/>
    </visual>
    <collision name="trunk_collision">
      <origin rpy="0 0 0" xyz="0 0 0"/>
      <geometry>
        <box size="0.3762 0.0935 0.114"/>
      </geometry>
    </collision>
    <inertial>
      <origin rpy="0 0 0" xyz="0.021112 0.0 -0.005366"/>
      <mass value="4.921"/>
      <inertia ixx="0.02448" ixy="0.00012166" ixz="0.0014849" iyy="0.098077" iyz="-3.12e-05" izz="0.107"/>
    </inertial>
  </link>
  <!-- Định nghĩa macro cho một chân -->
  <!-- prefix  Tên của chân lf  front left  rf  front right  lh  rear left  rh  rear right     -->
  <!-- side  Chân đối xứng với chân này 1 bên phải  âm 1  bên trái  Dùng để nhân chia với tọa độ -->
  <!-- use dae  Sử dụng mesh hay không True  sử dụng  False  không sử dụng -->
  <!-- pos  Chân trước hay chân sau  1  chân trước  âm 1  chân sau-->
  <!-- bắt đầu phần háng -->
  <!-- Hip Link -->
  <link name="front_left_hip_link">
    <visual name="front_left_hip_visual">
      <origin rpy="0 0 0" xyz="0 0 0"/>
      <geometry>
        <!-- <cylinder length="${hip_length}" radius="${hip_radius}"/> -->
        <mesh filename="file:///home/phieu/ros2-learning/src/install/first_robot/share/first_robot/meshes/hip.dae" scale="1 1 1"/>
        <!-- dài 2cm  cố định thân trên và các chân -->
      </geometry>
      <material name="blue"/>
    </visual>
    <collision name="front_left_hip_collision">
      <origin rpy="0 0 0" xyz="0 -0.0955 0"/>
      <geometry>
        <cylinder length="0.05" radius="0.056"/>
      </geometry>
    </collision>
    <inertial>
      <origin rpy="0 0 0" xyz="-0.0054 -0.00194 -0.000105"/>
      <mass value="0.678"/>
      <inertia ixx="0.00048" ixy="3.01e-06" ixz="1.11e-06" iyy="0.000884" iyz="1.42e-06" izz="0.000596"/>
    </inertial>
  </link>
  <joint description="Hip joint side -1 and pos 1" name="front_left_hip_joint" type="revolute">
    <parent link="trunk"/>
    <child link="front_left_hip_link"/>
    <origin rpy="0 0 0" xyz="0.1934 0.0465 0"/>
    <axis xyz="1 0 0"/>
    <dynamics damping="0.01" friction="0.2"/>
    <limit effort="23.7" lower="-1.0472" upper="1.0472" velocity="30.1"/>
    <!-- Vị trí gắn khớp háng vào body-->
  </joint>
  <!-- *** Bắt đầu phần đùi chân *** -->
  <!-- knee Link -->
  <link name="front_left_knee_link">
    <visual name="front_left_knee_visual">
      <origin rpy="0 0 0" xyz="0 0 0"/>
      <geometry>
        <mesh filename="file:///home/phieu/ros2-learning/src/install/first_robot/share/first_robot/meshes/knee.dae" scale="1 1 1"/>
        <!-- <origin rpy="${PI/2.0} 2.0 0" xyz="0 0 0"/> -->
      </geometry>
      <material name="green"/>
    </visual>
    <collision name="front_left_knee_collision">
      <origin rpy="0 0 0" xyz="0 0 0"/>
      <geometry>
        <box size="0.223 0.0345 0.044000000000000004"/>
      </geometry>
    </collision>
    <inertial>
      <origin rpy="0 0 0" xyz="-0.00374 -0.0223 -0.0327"/>
      <mass value="0.135862"/>
      <inertia ixx="0.00584" ixy="8.72e-05" ixz="-0.000289" iyy="0.0058" iyz="0.000808" izz="0.00103"/>
    </inertial>
  </link>
  <!-- knee Joint  Đùi  quay về sau  -->
  <joint description="Knee joint side -1 and pos 1" name="front_left_knee_joint" type="revolute">
    <origin rpy="0 0.45 0" xyz="0 0.0955 0"/>
    <parent link="front_left_hip_link"/>
    <!-- Gắn vào motor háng mô phỏng -->
    <child link="front_left_knee_link"/>
    <axis xyz="0 1 0"/>
    <dynamics damping="0.01" friction="0.2"/>
    <limit effort="30" lower="-1.57" upper="1.57" velocity="7.0"/>
    <limit effort="23.7" lower="-1.5708" upper="3.4907" velocity="30.1"/>
  </joint>
  <!-- *** Kết thúc phần đùi chân *** -->
  <!-- *** Bắt đầu phần cẳng chân *** -->
  <!-- ankle Link -->
  <link name="front_left_ankle_link">
    <visual name="front_left_ankle_visual">
      <origin rpy="0 0 0" xyz="0 0 0"/>
      <geometry>
        <!-- <box size="${ankle_length} ${ankle_width} ${ankle_height}"/> -->
        <mesh filename="file:///home/phieu/ros2-learning/src/install/first_robot/share/first_robot/meshes/ankle.dae" scale="1 1 1"/>
      </geometry>
      <!-- Màu tím -->
      <material name="purple"/>
    </visual>
    <collision name="front_left_ankle_collision">
      <origin rpy="0 0 0" xyz="0 0 0"/>
      <geometry>
        <box size="0.223 0.026000000000000002 0.026000000000000002"/>
      </geometry>
    </collision>
    <inertial>
      <origin rpy="0 0 0" xyz="0.00548 -0.000975 -0.115"/>
      <mass value="0.154"/>
      <inertia ixx="0.00108" ixy="3.4e-07" ixz="1.72e-05" iyy="0.0011" iyz="8.28e-06" izz="3.29e-05"/>
    </inertial>
  </link>
  <!-- ankle Joint  Cẳng chân  quay về trước 45  -->
  <joint name="front_left_ankle_joint" type="revolute">
    <origin rpy="0 -1.57 0" xyz="0 0 -0.213"/>
    <parent link="front_left_knee_link"/>
    <child link="front_left_ankle_link"/>
    <axis xyz="0 1 0"/>
    <dynamics damping="0.01" friction="0.2"/>
    <limit effort="35.55" lower="-1.0" upper="1.0" velocity="20.06"/>
  </joint>
  <!-- *** Kết thúc phần cẳng chân *** -->
  <!-- *** Bắt đầu phần bàn chân *** -->
  <!-- Foot Link -->
  <link name="front_left_foot_link">
    <visual name="front_left_foot_visual">
      <origin rpy="0 0 0" xyz="0 0 0"/>
      <geometry>
        <mesh filename="file:///home/phieu/ros2-learning/src/install/first_robot/share/first_robot/meshes/foot.dae" scale="1 1 1"/>
        <!-- <sphere radius="${foot_radius}"/> -->
      </geometry>
      <material name="black"/>
    </visual>
    <collision name="front_left_foot_collision">
      <origin rpy="0 0 0" xyz="0 0 0"/>
      <geometry>
        <sphere radius="0.02"/>
      </geometry>
    </collision>
    <inertial>
      <mass value="0.06"/>
      <inertia ixx="9.600000000000001e-06" ixy="0.0" ixz="0.0" iyy="9.600000000000001e-06" iyz="0.0" izz="9.600000000000001e-06"/>
    </inertial>
  </link>
  <!-- Foot Joint -->
  <joint name="front_left_foot_joint" type="fixed">
    <origin rpy="0 0 0" xyz="0 0 -0.213"/>
    <parent link="front_left_ankle_link"/>
    <child link="front_left_foot_link"/>
  </joint>
  <!-- Transmission cho các joint -->
  <transmission name="front_left_knee_trans">
    <type>transmission_interface/SimpleTransmission</type>
    <joint name="front_left_knee_joint"/>
    <actuator name="front_left_knee_motor">
      <mechanical_reduction>1</mechanical_reduction>
    </actuator>
  </transmission>
  <transmission name="front_left_ankle_trans">
    <type>transmission_interface/SimpleTransmission</type>
    <joint name="front_left_ankle_joint"/>
    <actuator name="front_left_ankle_motor">
      <mechanical_reduction>1</mechanical_reduction>
    </actuator>
  </transmission>
  <!-- bắt đầu phần háng -->
  <!-- Hip Link -->
  <link name="front_right_hip_link">
    <visual name="front_right_hip_visual">
      <origin rpy="3.141592653589793 0 0" xyz="0 0 0"/>
      <geometry>
        <!-- <cylinder length="${hip_length}" radius="${hip_radius}"/> -->
        <mesh filename="file:///home/phieu/ros2-learning/src/install/first_robot/share/first_robot/meshes/hip.dae" scale="1 1 1"/>
        <!-- dài 2cm  cố định thân trên và các chân -->
      </geometry>
      <material name="blue"/>
    </visual>
    <collision name="front_right_hip_collision">
      <origin rpy="0 0 0" xyz="0 0.0955 0"/>
      <geometry>
        <cylinder length="0.05" radius="0.056"/>
      </geometry>
    </collision>
    <inertial>
      <origin rpy="0 0 0" xyz="-0.0054 0.00194 -0.000105"/>
      <mass value="0.678"/>
      <inertia ixx="0.00048" ixy="-3.01e-06" ixz="1.11e-06" iyy="0.000884" iyz="-1.42e-06" izz="0.000596"/>
    </inertial>
  </link>
  <joint description="Hip joint side 1 and pos 1" name="front_right_hip_joint" type="revolute">
    <parent link="trunk"/>
    <child link="front_right_hip_link"/>
    <origin rpy="0 0 0" xyz="0.1934 -0.0465 0"/>
    <axis xyz="1 0 0"/>
    <dynamics damping="0.01" friction="0.2"/>
    <limit effort="23.7" lower="-1.0472" upper="1.0472" velocity="30.1"/>
    <!-- Vị trí gắn khớp háng vào body-->
  </joint>
  <!-- *** Bắt đầu phần đùi chân *** -->
  <!-- knee Link -->
  <link name="front_right_knee_link">
    <visual name="front_right_knee_visual">
      <origin rpy="0 0 0" xyz="0 0 0"/>
      <geometry>
        <mesh filename="file:///home/phieu/ros2-learning/src/install/first_robot/share/first_robot/meshes/knee_mirror.dae" scale="1 1 1"/>
        <!-- <origin rpy="${PI/2.0} 2.0 0" xyz="0 0 0"/> -->
      </geometry>
      <material name="green"/>
    </visual>
    <collision name="front_right_knee_collision">
      <origin rpy="0 0 0" xyz="0 0 0"/>
      <geometry>
        <box size="0.223 0.0345 0.044000000000000004"/>
      </geometry>
    </collision>
    <inertial>
      <origin rpy="0 0 0" xyz="-0.00374 0.0223 -0.0327"/>
      <mass value="0.135862"/>
      <inertia ixx="0.00584" ixy="-8.72e-05" ixz="-0.000289" iyy="0.0058" iyz="-0.000808" izz="0.00103"/>
    </inertial>
  </link>
  <!-- knee Joint  Đùi  quay về sau  -->
  <joint description="Knee joint side 1 and pos 1" name="front_right_knee_joint" type="revolute">
    <origin rpy="0 0.45 0" xyz="0 -0.0955 0"/>
    <parent link="front_right_hip_link"/>
    <!-- Gắn vào motor háng mô phỏng -->
    <child link="front_right_knee_link"/>
    <axis xyz="0 1 0"/>
    <dynamics damping="0.01" friction="0.2"/>
    <limit effort="30" lower="-1.57" upper="1.57" velocity="7.0"/>
    <limit effort="23.7" lower="-1.5708" upper="3.4907" velocity="30.1"/>
  </joint>
  <!-- *** Kết thúc phần đùi chân *** -->
  <!-- *** Bắt đầu phần cẳng chân *** -->
  <!-- ankle Link -->
  <link name="front_right_ankle_link">
    <visual name="front_right_ankle_visual">
      <origin rpy="0 0 0" xyz="0 0 0"/>
      <geometry>
        <!-- <box size="${ankle_length} ${ankle_width} ${ankle_height}"/> -->
        <mesh filename="file:///home/phieu/ros2-learning/src/install/first_robot/share/first_robot/meshes/ankle.dae" scale="1 1 1"/>
      </geometry>
      <!-- Màu tím -->
      <material name="purple"/>
    </visual>
    <collision name="front_right_ankle_collision">
      <origin rpy="0 0 0" xyz="0 0 0"/>
      <geometry>
        <box size="0.223 0.026000000000000002 0.026000000000000002"/>
      </geometry>
    </collision>
    <inertial>
      <origin rpy="0 0 0" xyz="0.00548 -0.000975 -0.115"/>
      <mass value="0.154"/>
      <inertia ixx="0.00108" ixy="3.4e-07" ixz="1.72e-05" iyy="0.0011" iyz="8.28e-06" izz="3.29e-05"/>
    </inertial>
  </link>
  <!-- ankle Joint  Cẳng chân  quay về trước 45  -->
  <joint name="front_right_ankle_joint" type="revolute">
    <origin rpy="0 -1.57 0" xyz="0 0 -0.213"/>
    <parent link="front_right_knee_link"/>
    <child link="front_right_ankle_link"/>
    <axis xyz="0 1 0"/>
    <dynamics damping="0.01" friction="0.2"/>
    <limit effort="35.55" lower="-1.0" upper="1.0" velocity="20.06"/>
  </joint>
  <!-- *** Kết thúc phần cẳng chân *** -->
  <!-- *** Bắt đầu phần bàn chân *** -->
  <!-- Foot Link -->
  <link name="front_right_foot_link">
    <visual name="front_right_foot_visual">
      <origin rpy="0 0 0" xyz="0 0 0"/>
      <geometry>
        <mesh filename="file:///home/phieu/ros2-learning/src/install/first_robot/share/first_robot/meshes/foot.dae" scale="1 1 1"/>
        <!-- <sphere radius="${foot_radius}"/> -->
      </geometry>
      <material name="black"/>
    </visual>
    <collision name="front_right_foot_collision">
      <origin rpy="0 0 0" xyz="0 0 0"/>
      <geometry>
        <sphere radius="0.02"/>
      </geometry>
    </collision>
    <inertial>
      <mass value="0.06"/>
      <inertia ixx="9.600000000000001e-06" ixy="0.0" ixz="0.0" iyy="9.600000000000001e-06" iyz="0.0" izz="9.600000000000001e-06"/>
    </inertial>
  </link>
  <!-- Foot Joint -->
  <joint name="front_right_foot_joint" type="fixed">
    <origin rpy="0 0 0" xyz="0 0 -0.213"/>
    <parent link="front_right_ankle_link"/>
    <child link="front_right_foot_link"/>
  </joint>
  <!-- Transmission cho các joint -->
  <transmission name="front_right_knee_trans">
    <type>transmission_interface/SimpleTransmission</type>
    <joint name="front_right_knee_joint"/>
    <actuator name="front_right_knee_motor">
      <mechanical_reduction>1</mechanical_reduction>
    </actuator>
  </transmission>
  <transmission name="front_right_ankle_trans">
    <type>transmission_interface/SimpleTransmission</type>
    <joint name="front_right_ankle_joint"/>
    <actuator name="front_right_ankle_motor">
      <mechanical_reduction>1</mechanical_reduction>
    </actuator>
  </transmission>
  <!-- bắt đầu phần háng -->
  <!-- Hip Link -->
  <link name="rear_left_hip_link">
    <visual name="rear_left_hip_visual">
      <origin rpy="0 3.141592653589793 0" xyz="0 0 0"/>
      <geometry>
        <!-- <cylinder length="${hip_length}" radius="${hip_radius}"/> -->
        <mesh filename="file:///home/phieu/ros2-learning/src/install/first_robot/share/first_robot/meshes/hip.dae" scale="1 1 1"/>
        <!-- dài 2cm  cố định thân trên và các chân -->
      </geometry>
      <material name="blue"/>
    </visual>
    <collision name="rear_left_hip_collision">
      <origin rpy="0 0 0" xyz="0 -0.0955 0"/>
      <geometry>
        <cylinder length="0.05" radius="0.056"/>
      </geometry>
    </collision>
    <inertial>
      <origin rpy="0 0 0" xyz="0.0054 -0.00194 -0.000105"/>
      <mass value="0.678"/>
      <inertia ixx="0.00048" ixy="-3.01e-06" ixz="-1.11e-06" iyy="0.000884" iyz="1.42e-06" izz="0.000596"/>
    </inertial>
  </link>
  <joint description="Hip joint side -1 and pos -1" name="rear_left_hip_joint" type="revolute">
    <parent link="trunk"/>
    <child link="rear_left_hip_link"/>
    <origin rpy="0 0 0" xyz="-0.1934 0.0465 0"/>
    <axis xyz="1 0 0"/>
    <dynamics damping="0.01" friction="0.2"/>
    <limit effort="23.7" lower="-1.0472" upper="1.0472" velocity="30.1"/>
    <!-- Vị trí gắn khớp háng vào body-->
  </joint>
  <!-- *** Bắt đầu phần đùi chân *** -->
  <!-- knee Link -->
  <link name="rear_left_knee_link">
    <visual name="rear_left_knee_visual">
      <origin rpy="0 0 0" xyz="0 0 0"/>
      <geometry>
        <mesh filename="file:///home/phieu/ros2-learning/src/install/first_robot/share/first_robot/meshes/knee.dae" scale="1 1 1"/>
        <!-- <origin rpy="${PI/2.0} 2.0 0" xyz="0 0 0"/> -->
      </geometry>
      <material name="green"/>
    </visual>
    <collision name="rear_left_knee_collision">
      <origin rpy="0 0 0" xyz="0 0 0"/>
      <geometry>
        <box size="0.223 0.0345 0.044000000000000004"/>
      </geometry>
    </collision>
    <inertial>
      <origin rpy="0 0 0" xyz="-0.00374 -0.0223 -0.0327"/>
      <mass value="0.135862"/>
      <inertia ixx="0.00584" ixy="8.72e-05" ixz="-0.000289" iyy="0.0058" iyz="0.000808" izz="0.00103"/>
    </inertial>
  </link>
  <!-- knee Joint  Đùi  quay về sau  -->
  <joint description="Knee joint side -1 and pos -1" name="rear_left_knee_joint" type="revolute">
    <origin rpy="0 0.45 0" xyz="0 0.0955 0"/>
    <parent link="rear_left_hip_link"/>
    <!-- Gắn vào motor háng mô phỏng -->
    <child link="rear_left_knee_link"/>
    <axis xyz="0 1 0"/>
    <dynamics damping="0.01" friction="0.2"/>
    <limit effort="30" lower="-1.57" upper="1.57" velocity="7.0"/>
    <limit effort="23.7" lower="-1.5708" upper="3.4907" velocity="30.1"/>
  </joint>
  <!-- *** Kết thúc phần đùi chân *** -->
  <!-- *** Bắt đầu phần cẳng chân *** -->
  <!-- ankle Link -->
  <link name="rear_left_ankle_link">
    <visual name="rear_left_ankle_visual">
      <origin rpy="0 0 0" xyz="0 0 0"/>
      <geometry>
        <!-- <box size="${ankle_length} ${ankle_width} ${ankle_height}"/> -->
        <mesh filename="file:///home/phieu/ros2-learning/src/install/first_robot/share/first_robot/meshes/ankle.dae" scale="1 1 1"/>
      </geometry>
      <!-- Màu tím -->
      <material name="purple"/>
    </visual>
    <collision name="rear_left_ankle_collision">
      <origin rpy="0 0 0" xyz="0 0 0"/>
      <geometry>
        <box size="0.223 0.026000000000000002 0.026000000000000002"/>
      </geometry>
    </collision>
    <inertial>
      <origin rpy="0 0 0" xyz="0.00548 -0.000975 -0.115"/>
      <mass value="0.154"/>
      <inertia ixx="0.00108" ixy="3.4e-07" ixz="1.72e-05" iyy="0.0011" iyz="8.28e-06" izz="3.29e-05"/>
    </inertial>
  </link>
  <!-- ankle Joint  Cẳng chân  quay về trước 45  -->
  <joint name="rear_left_ankle_joint" type="revolute">
    <origin rpy="0 -1.57 0" xyz="0 0 -0.213"/>
    <parent link="rear_left_knee_link"/>
    <child link="rear_left_ankle_link"/>
    <axis xyz="0 1 0"/>
    <dynamics damping="0.01" friction="0.2"/>
    <limit effort="35.55" lower="-1.0" upper="1.0" velocity="20.06"/>
  </joint>
  <!-- *** Kết thúc phần cẳng chân *** -->
  <!-- *** Bắt đầu phần bàn chân *** -->
  <!-- Foot Link -->
  <link name="rear_left_foot_link">
    <visual name="rear_left_foot_visual">
      <origin rpy="0 0 0" xyz="0 0 0"/>
      <geometry>
        <mesh filename="file:///home/phieu/ros2-learning/src/install/first_robot/share/first_robot/meshes/foot.dae" scale="1 1 1"/>
        <!-- <sphere radius="${foot_radius}"/> -->
      </geometry>
      <material name="black"/>
    </visual>
    <collision name="rear_left_foot_collision">
      <origin rpy="0 0 0" xyz="0 0 0"/>
      <geometry>
        <sphere radius="0.02"/>
      </geometry>
    </collision>
    <inertial>
      <mass value="0.06"/>
      <inertia ixx="9.600000000000001e-06" ixy="0.0" ixz="0.0" iyy="9.600000000000001e-06" iyz="0.0" izz="9.600000000000001e-06"/>
    </inertial>
  </link>
  <!-- Foot Joint -->
  <joint name="rear_left_foot_joint" type="fixed">
    <origin rpy="0 0 0" xyz="0 0 -0.213"/>
    <parent link="rear_left_ankle_link"/>
    <child link="rear_left_foot_link"/>
  </joint>
  <!-- Transmission cho các joint -->
  <transmission name="rear_left_knee_trans">
    <type>transmission_interface/SimpleTransmission</type>
    <joint name="rear_left_knee_joint"/>
    <actuator name="rear_left_knee_motor">
      <mechanical_reduction>1</mechanical_reduction>
    </actuator>
  </transmission>
  <transmission name="rear_left_ankle_trans">
    <type>transmission_interface/SimpleTransmission</type>
    <joint name="rear_left_ankle_joint"/>
    <actuator name="rear_left_ankle_motor">
      <mechanical_reduction>1</mechanical_reduction>
    </actuator>
  </transmission>
  <!-- bắt đầu phần háng -->
  <!-- Hip Link -->
  <link name="rear_right_hip_link">
    <visual name="rear_right_hip_visual">
      <origin rpy="3.141592653589793 3.141592653589793 0" xyz="0 0 0"/>
      <geometry>
        <!-- <cylinder length="${hip_length}" radius="${hip_radius}"/> -->
        <mesh filename="file:///home/phieu/ros2-learning/src/install/first_robot/share/first_robot/meshes/hip.dae" scale="1 1 1"/>
        <!-- dài 2cm  cố định thân trên và các chân -->
      </geometry>
      <material name="blue"/>
    </visual>
    <collision name="rear_right_hip_collision">
      <origin rpy="0 0 0" xyz="0 0.0955 0"/>
      <geometry>
        <cylinder length="0.05" radius="0.056"/>
      </geometry>
    </collision>
    <inertial>
      <origin rpy="0 0 0" xyz="0.0054 0.00194 -0.000105"/>
      <mass value="0.678"/>
      <inertia ixx="0.00048" ixy="3.01e-06" ixz="-1.11e-06" iyy="0.000884" iyz="-1.42e-06" izz="0.000596"/>
    </inertial>
  </link>
  <joint description="Hip joint side 1 and pos -1" name="rear_right_hip_joint" type="revolute">
    <parent link="trunk"/>
    <child link="rear_right_hip_link"/>
    <origin rpy="0 0 0" xyz="-0.1934 -0.0465 0"/>
    <axis xyz="1 0 0"/>
    <dynamics damping="0.01" friction="0.2"/>
    <limit effort="23.7" lower="-1.0472" upper="1.0472" velocity="30.1"/>
    <!-- Vị trí gắn khớp háng vào body-->
  </joint>
  <!-- *** Bắt đầu phần đùi chân *** -->
  <!-- knee Link -->
  <link name="rear_right_knee_link">
    <visual name="rear_right_knee_visual">
      <origin rpy="0 0 0" xyz="0 0 0"/>
      <geometry>
        <mesh filename="file:///home/phieu/ros2-learning/src/install/first_robot/share/first_robot/meshes/knee_mirror.dae" scale="1 1 1"/>
        <!-- <origin rpy="${PI/2.0} 2.0 0" xyz="0 0 0"/> -->
      </geometry>
      <material name="green"/>
    </visual>
    <collision name="rear_right_knee_collision">
      <origin rpy="0 0 0" xyz="0 0 0"/>
      <geometry>
        <box size="0.223 0.0345 0.044000000000000004"/>
      </geometry>
    </collision>
    <inertial>
      <origin rpy="0 0 0" xyz="-0.00374 0.0223 -0.0327"/>
      <mass value="0.135862"/>
      <inertia ixx="0.00584" ixy="-8.72e-05" ixz="-0.000289" iyy="0.0058" iyz="-0.000808" izz="0.00103"/>
    </inertial>
  </link>
  <!-- knee Joint  Đùi  quay về sau  -->
  <joint description="Knee joint side 1 and pos -1" name="rear_right_knee_joint" type="revolute">
    <origin rpy="0 0.45 0" xyz="0 -0.0955 0"/>
    <parent link="rear_right_hip_link"/>
    <!-- Gắn vào motor háng mô phỏng -->
    <child link="rear_right_knee_link"/>
    <axis xyz="0 1 0"/>
    <dynamics damping="0.01" friction="0.2"/>
    <limit effort="30" lower="-1.57" upper="1.57" velocity="7.0"/>
    <limit effort="23.7" lower="-1.5708" upper="3.4907" velocity="30.1"/>
  </joint>
  <!-- *** Kết thúc phần đùi chân *** -->
  <!-- *** Bắt đầu phần cẳng chân *** -->
  <!-- ankle Link -->
  <link name="rear_right_ankle_link">
    <visual name="rear_right_ankle_visual">
      <origin rpy="0 0 0" xyz="0 0 0"/>
      <geometry>
        <!-- <box size="${ankle_length} ${ankle_width} ${ankle_height}"/> -->
        <mesh filename="file:///home/phieu/ros2-learning/src/install/first_robot/share/first_robot/meshes/ankle.dae" scale="1 1 1"/>
      </geometry>
      <!-- Màu tím -->
      <material name="purple"/>
    </visual>
    <collision name="rear_right_ankle_collision">
      <origin rpy="0 0 0" xyz="0 0 0"/>
      <geometry>
        <box size="0.223 0.026000000000000002 0.026000000000000002"/>
      </geometry>
    </collision>
    <inertial>
      <origin rpy="0 0 0" xyz="0.00548 -0.000975 -0.115"/>
      <mass value="0.154"/>
      <inertia ixx="0.00108" ixy="3.4e-07" ixz="1.72e-05" iyy="0.0011" iyz="8.28e-06" izz="3.29e-05"/>
    </inertial>
  </link>
  <!-- ankle Joint  Cẳng chân  quay về trước 45  -->
  <joint name="rear_right_ankle_joint" type="revolute">
    <origin rpy="0 -1.57 0" xyz="0 0 -0.213"/>
    <parent link="rear_right_knee_link"/>
    <child link="rear_right_ankle_link"/>
    <axis xyz="0 1 0"/>
    <dynamics damping="0.01" friction="0.2"/>
    <limit effort="35.55" lower="-1.0" upper="1.0" velocity="20.06"/>
  </joint>
  <!-- *** Kết thúc phần cẳng chân *** -->
  <!-- *** Bắt đầu phần bàn chân *** -->
  <!-- Foot Link -->
  <link name="rear_right_foot_link">
    <visual name="rear_right_foot_visual">
      <origin rpy="0 0 0" xyz="0 0 0"/>
      <geometry>
        <mesh filename="file:///home/phieu/ros2-learning/src/install/first_robot/share/first_robot/meshes/foot.dae" scale="1 1 1"/>
        <!-- <sphere radius="${foot_radius}"/> -->
      </geometry>
      <material name="black"/>
    </visual>
    <collision name="rear_right_foot_collision">
      <origin rpy="0 0 0" xyz="0 0 0"/>
      <geometry>
        <sphere radius="0.02"/>
      </geometry>
    </collision>
    <inertial>
      <mass value="0.06"/>
      <inertia ixx="9.600000000000001e-06" ixy="0.0" ixz="0.0" iyy="9.600000000000001e-06" iyz="0.0" izz="9.600000000000001e-06"/>
    </inertial>
  </link>
  <!-- Foot Joint -->
  <joint name="rear_right_foot_joint" type="fixed">
    <origin rpy="0 0 0" xyz="0 0 -0.213"/>
    <parent link="rear_right_ankle_link"/>
    <child link="rear_right_foot_link"/>
  </joint>
  <!-- Transmission cho các joint -->
  <transmission name="rear_right_knee_trans">
    <type>transmission_interface/SimpleTransmission</type>
    <joint name="rear_right_knee_joint"/>
    <actuator name="rear_right_knee_motor">
      <mechanical_reduction>1</mechanical_reduction>
    </actuator>
  </transmission>
  <transmission name="rear_right_ankle_trans">
    <type>transmission_interface/SimpleTransmission</type>
    <joint name="rear_right_ankle_joint"/>
    <actuator name="rear_right_ankle_motor">
      <mechanical_reduction>1</mechanical_reduction>
    </actuator>
  </transmission>
  <ros2_control name="FirstRobot" type="system">
    <hardware>
      <plugin>gz_ros2_control/GazeboSimSystem</plugin>
    </hardware>
    <joint name="front_left_hip_joint">
      <command_interface name="position"/>
      <state_interface name="position"/>
      <state_interface name="velocity"/>
    </joint>
    <joint name="front_left_knee_joint">
      <command_interface name="position"/>
      <state_interface name="position"/>
      <state_interface name="velocity"/>
    </joint>
    <joint name="front_left_ankle_joint">
      <command_interface name="position"/>
      <state_interface name="position"/>
      <state_interface name="velocity"/>
    </joint>
    <joint name="front_right_hip_joint">
      <command_interface name="position"/>
      <state_interface name="position"/>
      <state_interface name="velocity"/>
    </joint>
    <joint name="front_right_knee_joint">
      <command_interface name="position"/>
      <state_interface name="position"/>
      <state_interface name="velocity"/>
    </joint>
    <joint name="front_right_ankle_joint">
      <command_interface name="position"/>
      <state_interface name="position"/>
      <state_interface name="velocity"/>
    </joint>
    <joint name="rear_left_hip_joint">
      <command_interface name="position"/>
      <state_interface name="position"/>
      <state_interface name="velocity"/>
    </joint>
    <joint name="rear_left_knee_joint">
      <command_interface name="position"/>
      <state_interface name="position"/>
      <state_interface name="velocity"/>
    </joint>
    <joint name="rear_left_ankle_joint">
      <command_interface name="position"/>
      <state_interface name="position"/>
      <state_interface name="velocity"/>
    </joint>
    <joint name="rear_right_hip_joint">
      <command_interface name="position"/>
      <state_interface name="position"/>
      <state_interface name="velocity"/>
    </joint>
    <joint name="rear_right_knee_joint">
      <command_interface name="position"/>
      <state_interface name="position"/>
      <state_interface name="velocity"/>
    </joint>
    <joint name="rear_right_ankle_joint">
      <command_interface name="position"/>
      <state_interface name="position"/>
      <state_interface name="velocity"/>
    </joint>
  </ros2_control>
  <gazebo>
    <plugin filename="gz_ros2_control-system" name="gz_ros2_control::GazeboSimROS2ControlPlugin">
      <parameters>/home/phieu/ros2-learning/src/install/first_robot/share/first_robot/config/ros_control.yaml</parameters>
    </plugin>
  </gazebo>
  <joint name="laser_joint" type="fixed">
    <parent link="base_link"/>
    <child link="lidar_link"/>
    <origin rpy="0 0 0" xyz="0 0 0"/>
  </joint>
  <link name="lidar_link">
    <visual>
      <geometry>
        <cylinder length="0.02" radius="0.025"/>
      </geometry>
      <material name="red"/>
    </visual>
    <collision>
      <geometry>
        <cylinder length="0.02" radius="0.025"/>
      </geometry>
    </collision>
    <inertial>
      <origin rpy="0 0 0" xyz="0 0 0"/>
      <mass value="0.01"/>
      <inertia ixx="6.5833333333333335e-06" ixy="0.0" ixz="0.0" iyy="6.5833333333333335e-06" iyz="0.0" izz="1.2500000000000002e-05"/>
    </inertial>
  </link>
  <gazebo reference="lidar_link">
    <sensor name="lidar_link" type="gpu_lidar">
      <always_on>true</always_on>
      <update_rate>2</update_rate>
      <topic>/scan</topic>
      <visualize>true</visualize>
      <frame_id>lidar_link</frame_id>
      <gz_frame_id>lidar_link</gz_frame_id>
      <ign_frame_id>lidar_link</ign_frame_id>
      <ros>
        <namespace>/</namespace>
        <remapping>scan:=scan</remapping>
      </ros>
      <ray>
        <scan>
          <horizontal>
            <samples>720</samples>
            <resolution>1</resolution>
            <min_angle>-1.5708</min_angle>
            <max_angle>1.5708</max_angle>
          </horizontal>
        </scan>
        <range>
          <min>0.1</min>
          <max>10.0</max>
        </range>
        <noise>
          <type>gaussian</type>
          <mean>0.0</mean>
          <stddev>0.01</stddev>
        </noise>
      </ray>
      <!-- <plugin
                filename="gz-sim-sensors-system"
                name="gz::sim::systems::Sensors">
                <render_engine>ogre</render_engine>
            </plugin> -->
    </sensor>
  </gazebo>
  <joint name="camera_joint" type="fixed">
    <parent link="base_link"/>
    <child link="camera_link"/>
    <origin rpy="0 0 0" xyz="0.25 0 0.043"/>
  </joint>
  <link name="camera_link">
    <visual>
      <origin rpy="0 0 0" xyz="0 0 0"/>
      <geometry>
        <sphere radius="0.005"/>
      </geometry>
      <material name="red"/>
    </visual>
    <collision>
      <origin rpy="0 0 0" xyz="0 0 0"/>
      <geometry>
        <sphere radius="0.005"/>
      </geometry>
    </collision>
    <inertial>
      <mass value="0.005"/>
      <origin rpy="0 0 0" xyz="0 0 0"/>
      <inertia ixx="0.0001" ixy="0" ixz="0" iyy="0.0001" iyz="0" izz="0.0001"/>
    </inertial>
  </link>
  <gazebo reference="camera_link">
    <material>Gazebo/Red</material>
    <sensor name="camera" type="camera">
      <camera>
        <horizontal_fov>1.047</horizontal_fov>
        <image>
          <width>320</width>
          <height>240</height>
        </image>
        <clip>
          <near>0.1</near>
          <far>100</far>
        </clip>
      </camera>
      <always_on>1</always_on>
      <update_rate>30</update_rate>
      <visualize>true</visualize>
      <topic>camera</topic>
    </sensor>
  </gazebo>
  <link name="imu_link">
    <inertial>
      <mass value="0.001"/>
      <origin rpy="0 0 0" xyz="0 0 0"/>
      <inertia ixx="0.0001" ixy="0" ixz="0" iyy="0.0001" iyz="0" izz="0.0001"/>
    </inertial>
    <visual>
      <origin rpy="0 0 0" xyz="0 0 0"/>
      <geometry>
        <box size="0.001 0.001 0.01"/>
      </geometry>
      <material name="yellow"/>
    </visual>
    <collision>
      <origin rpy="0 0 0" xyz="0 0 0"/>
      <geometry>
        <box size=".001 .001 .01"/>
      </geometry>
    </collision>
  </link>
  <joint name="imu_joint" type="fixed">
    <parent link="trunk"/>
    <child link="imu_link"/>
    <origin rpy="0 0 0" xyz="0 0 0.1"/>
    <!-- Đặt IMU gần trọng tâm -->
  </joint>
  <gazebo reference="imu_link">
    <sensor name="imu_sensor" type="imu">
      <always_on>true</always_on>
      <update_rate>200</update_rate>
      <topic>imu/data</topic>
      <plugin filename="gz-sim-imu-system" name="gz::sim::systems::Imu">
        <ros>
          <namespace>/</namespace>
        </ros>
      </plugin>
      <imu>
        <noise type="gaussian">
          <rate>
            <mean>0.0</mean>
            <stddev>0.005</stddev>
            <!-- Giảm nhiễu -->
          </rate>
          <accel>
            <mean>0.0</mean>
            <stddev>0.005</stddev>
          </accel>
        </noise>
      </imu>
    </sensor>
  </gazebo>
</robot>
